Workbook

Sheet 0_條件與假設
A1: 秀泰新辦公室（總部）選址分析 — 2026-09-24 新條件重跑
A2: 資料日期：2026-09-24。所有數字照來源原文；未揭露的欄位留空並以淺橘底標示，不估算。藍字＝輸入值，黑字＝公式。
A4: 項目 | B4: 數值 | C4: 說明
A5: 實坪門檻（坪，主建物＋附屬，不含公設） | B5: 220 | C5: 使用者條件：「實際」坪數約220坪起
A6: 理想月租上限（元，含稅） | B6: 450000 | C6: 使用者條件：45萬內
A7: 月租硬上限（元，含稅） | B7: 550000 | C7: 使用者條件：左右不要超過55萬
A8: 捷運步行門檻（分鐘） | B8: 10 | C8: 捷運以綠(松山新店)／紅(淡水信義)／藍(板南)為主；步行分＝直線距離×1.3÷80m
A9: 營業稅率 | B9: 0.05 | C9: 未稅價×1.05換算含稅
A11: 分級規則
A12: 第一優先 | B12: 實坪≥220（有謄本／物調表／房仲頁分項）＋ 月租≤45萬 ＋ 五區內 ＋ 綠紅藍線步行≤10分
A13: 第二優先 | B13: 實坪≥220 已確認 ＋ 月租≤55萬；捷運可為11～16分（標示）
A14: 待確認實坪 | B14: 權狀≥240坪、月租≤55萬、交通可，但實坪未揭露 → 需向仲介索取謄本／物調表
A15: 不符合 | B15: 實坪<220、權狀<240且無分項、月租>55萬、地下室／1樓、非五區、大直、附近無綠紅藍線
A17: 本輪結果
A18: 第一優先 | B18: =COUNTIF(A_總表!A:A,"第一優先") -> 1
A19: 第二優先 | B19: =COUNTIF(A_總表!A:A,"第二優先") -> 5
A20: 待確認實坪 | B20: =COUNTIF(A_總表!A:A,"待確認實坪") -> 13
A21: 不符合 | B21: =COUNTIF(A_總表!A:A,"不符合") -> 61
A22: 合計 | B22: =SUM(B18:B21) -> 80
A24: 分頁說明
A25: A_總表 | B25: 全部案件（新增＋上一版），依新條件分級排序；含公式驗算欄
A26: B_優先案詳情 | B26: 第一／第二優先與待確認案的完整資料、來源、聯絡人、缺漏
A27: C_待確認清單 | B27: 每一案還缺什麼、該問誰
A28: D_捷運距離 | B28: 每案最近綠／紅／藍線站、距離與計算依據
A29: E_591篩選紀錄 | B29: 591 商辦 116 筆逐筆對應到案號
A30: F_尚揚物調表 | B30: 尚揚國際提供 7 份物調表原文數字
A31: G_傑森愛華0923清單 | B31: 傑森愛華 2026/9/23 清單 13 筆原文＋對應
A32: H_搜尋範圍與來源 | B32: 各網站搜尋條件、筆數、被擋情形
A33: P_精選案件 | B33: Kevina 指定的精選案件（9/30、10/12 提供；10/12 重新查核刊登狀態）並排比較，含未達條件的案件與原因

Sheet P_精選案件
A1: Kevina 推薦的 18 案 — 並排比較
A2: 依使用者指定的連結整理（9/30 給 8 個、10/12 再給 12 個，其中 2 個與既有案同戶）；10/12 全部重新查核刊登狀態。分級仍依原條件，未達條件的案件排在後面，原因見最後一欄。藍字＝來源原文數字，黑字＝公式；淺橘底＝未揭露／有變動。月總成本只在管理費有數字時計算。
A4: 案號 | B4: 案名 | C4: 分級 | D4: 行政區 | E4: 地址 | F4: 樓層 | G4: 權狀坪 | H4: 實坪 (主+附) | I4: 月租(含稅) | J4: 租金原文／稅別 | K4: 管理費(月) | L4: 月總成本 (公式) | M4: 每權狀坪月租 (公式) | N4: 實坪≥門檻 (公式) | O4: 租金級距 (公式) | P4: 最近綠紅藍站 | Q4: 路線 | R4: 距離(m) | S4: 步行(分) | T4: 捷運判定 (公式) | U4: 屋況／廁所 | V4: 租期 | W4: 押金 | X4: 刊登查核 | Y4: 缺漏／待確認 | Z4: 聯絡人 | AA4: 您提供的連結 | AB4: Google 地圖 | AC4: 判定說明（未達條件原因）
A5: N04 | B5: 信義大樓 10F | C5: 第二優先 | D5: 信義 | E5: 松仁路（信義大樓） | F5: 10F/23F | G5: 330.22 | H5: 300.43 | I5: 480000 | J5: 480,000（591 21537848，稅別未寫）；同戶信義房屋刊登577,885；⚠ 9/30 591 21537848 已下架，信義 C904200 現刊 577,885 | K5: 49533 | L5: =IF(OR(I5="",K5=""),"管理費缺",I5+K5) -> 529533 | M5: =IF(OR(I5="",G5=""),"",I5/G5) -> 1453.5764 | N5: =IF(H5="","未揭露",IF(H5>=0_條件與假設!$B$5,"✓","✗")) -> ✓ | O5: =IF(I5="","未提供",IF(I5<=0_條件與假設!$B$6,"≤45萬",IF(I5<=0_條件與假設!$B$7,"45～55萬","超過55萬"))) -> 45～55萬 | P5: 象山 | Q5: 紅 | R5: 950 | S5: 16 | T5: =IF(S5="","未確認",IF(S5<=0_條件與假設!$B$8,"✓",IF(S5<=16,"△ 11～16分","✗"))) -> △ 11～16分 | U5: 廁所新：廁所為新裝修（信義房屋 C904200 照片 C：檯面式洗手台、木紋隔間）；辦公區天花為開放式未封板。 | V5: 591：兩年 | W5: — | X5: 9/30：信義 C904200 刊登中，577,885／權狀330.22坪（與前次相同）；⚠ 591 21537848（48萬）已下架；10/12 再查：信義 C904200 仍為 577,885；591 21537848 仍下架 | Y5: 591 48萬刊登已下架（9/30），現存刊登為信義 577,885（超過55萬）；租金稅別未寫；兩方報價不同 | Z5: 傑森愛華 張先生 0931-330-823 | AA5: 開啟 | AB5: 開啟地圖 | AC5: 坪數符合；實坪300.43 · 月租48.0萬（45～55萬） · 捷運象山(紅) 16分（>10分）
A6: N08 | B6: 松江路 3F（松江南京站） | C6: 待確認實坪 | D6: 中山 | E6: 松江路 | F6: 3F/12F | G6: 302 | I6: 540837 | J6: 515,083 未含營業稅（591 21635155）→ 含稅 540,837 | L6: =IF(OR(I6="",K6=""),"管理費缺",I6+K6) -> 管理費缺 | M6: =IF(OR(I6="",G6=""),"",I6/G6) -> 1790.851 | N6: =IF(H6="","未揭露",IF(H6>=0_條件與假設!$B$5,"✓","✗")) -> 未揭露 | O6: =IF(I6="","未提供",IF(I6<=0_條件與假設!$B$6,"≤45萬",IF(I6<=0_條件與假設!$B$7,"45～55萬","超過55萬"))) -> 45～55萬 | P6: 松江南京 | Q6: 綠 | R6: 156 | S6: 3 | T6: =IF(S6="","未確認",IF(S6<=0_條件與假設!$B$8,"✓",IF(S6<=16,"△ 11～16分","✗"))) -> ✓ | U6: 廁所無照片：591 只有 1 張照片（捷運出口），室內與廁所都沒有拍。需現勘。 | V6: 一年 | W6: 面議 | X6: 9/30：591 22017413 刊登中，515,083（未稅）／302.99坪；同戶 21635155 也仍刊登；10/12 再查：22017413、21635155 仍刊登，515,083 | Y6: 實坪未揭露；管理費未提供；廁所需現勘 | Z6: 東家國際 蔡泳翰 0912-816-677；兆淇 鄭先生 0960-539-161 | AA6: 開啟 | AB6: 開啟地圖 | AC6: 待確認：實坪未揭露（權狀302坪）；已符合：月租54.1萬（45～55萬） · 松江南京(綠) 3分
A7: S11 | B7: 八德大樓 5F（出租285.67坪） | C7: 待確認實坪 | D7: 中山 | E7: 八德路二段 | F7: 5F/12F | G7: 285.67 | I7: 428505 | J7: 428,505（信義刊登）；591 21804249 285坪 427,500（1,500/坪） | K7: 47136 | L7: =IF(OR(I7="",K7=""),"管理費缺",I7+K7) -> 475641 | M7: =IF(OR(I7="",G7=""),"",I7/G7) -> 1500 | N7: =IF(H7="","未揭露",IF(H7>=0_條件與假設!$B$5,"✓","✗")) -> 未揭露 | O7: =IF(I7="","未提供",IF(I7<=0_條件與假設!$B$6,"≤45萬",IF(I7<=0_條件與假設!$B$7,"45～55萬","超過55萬"))) -> ≤45萬 | P7: 忠孝復興 | Q7: 藍 | R7: 620 | S7: 11 | T7: =IF(S7="","未確認",IF(S7<=0_條件與假設!$B$8,"✓",IF(S7<=16,"△ 11～16分","✗"))) -> △ 11～16分 | U7: 廁所新：廁所新裝修（信義 CZ05585 照片 D、G：石材檯面、新式小便斗、木紋隔間）；茶水間新（照片 J）；電梯廳石材。 | V7: — | W7: — | X7: 9/30：信義 CZ05585 刊登中，428,505／出租285.67坪（與前次相同）；10/12 再查：CZ05585 仍為 428,505／285.67坪 | Y7: 出租部分實坪未揭露；稅別未寫 | Z7: 信義 林嘉君 0912-313-517 | AA7: 開啟 | AB7: 開啟地圖 | AC7: 待確認：實坪未揭露（權狀285.67坪） · 捷運忠孝復興(藍) 11分（>10分）；已符合：月租42.9萬
A8: N10 | B8: 光復北路11巷 2F（南京三民站） | C8: 待確認實坪 | D8: 松山 | E8: 光復北路11巷 | F8: 2F/14F | G8: 283 | I8: 534870 | J8: 509,400 未稅（591 22062249、傑森愛華清單第2頁）→ 含稅 534,870 | L8: =IF(OR(I8="",K8=""),"管理費缺",I8+K8) -> 管理費缺 | M8: =IF(OR(I8="",G8=""),"",I8/G8) -> 1890 | N8: =IF(H8="","未揭露",IF(H8>=0_條件與假設!$B$5,"✓","✗")) -> 未揭露 | O8: =IF(I8="","未提供",IF(I8<=0_條件與假設!$B$6,"≤45萬",IF(I8<=0_條件與假設!$B$7,"45～55萬","超過55萬"))) -> 45～55萬 | P8: 南京三民 | Q8: 綠 | R8: 88 | S8: 2 | T8: =IF(S8="","未確認",IF(S8<=0_條件與假設!$B$8,"✓",IF(S8<=16,"△ 11～16分","✗"))) -> ✓ | U8: 廁所無照片：591 只有 2 張（空室、捷運站），沒有拍廁所。需現勘。 | V8: 3年 | W8: 3個月 | X8: 9/30：591 22062249 刊登中，509,400（未稅）／283坪（與前次相同）；10/12 再查：22062249 仍為 509,400／283坪 | Y8: 實坪未揭露；大樓名稱為推定；管理費未提供；廁所需現勘 | Z8: 易信國際 王先生 0955-866-400；傑森愛華 張先生 0931-330823 | AA8: 開啟 | AB8: 開啟地圖 | AC8: 待確認：實坪未揭露（權狀283坪）；已符合：月租53.5萬（45～55萬） · 南京三民(綠) 2分
A9: N15 | B9: 民生東路二段 6F（仲介稱使用約226坪） | C9: 待確認實坪 | D9: 中山 | E9: 民生東路二段 | F9: 6F/12F | G9: 255.18 | I9: 507565 | J9: 483,395 未含稅（591 21595066）→ 含稅 507,565 | L9: =IF(OR(I9="",K9=""),"管理費缺",I9+K9) -> 管理費缺 | M9: =IF(OR(I9="",G9=""),"",I9/G9) -> 1989.0469 | N9: =IF(H9="","未揭露",IF(H9>=0_條件與假設!$B$5,"✓","✗")) -> 未揭露 | O9: =IF(I9="","未提供",IF(I9<=0_條件與假設!$B$6,"≤45萬",IF(I9<=0_條件與假設!$B$7,"45～55萬","超過55萬"))) -> 45～55萬 | P9: 行天宮(橘) 188m | T9: =IF(S9="","未確認",IF(S9<=0_條件與假設!$B$8,"✓",IF(S9<=16,"△ 11～16分","✗"))) -> 未確認 | U9: 廁所新：廁所為新裝修（591 21985150 照片 8、9：深色石材牆面、檯面式洗手台、新式小便斗）；辦公區天花有部分線材外露待整理；同戶 591 21812612 內文寫「廁所設於室內」。 | V9: 兩年～3年 | W9: 面議 | X9: 9/30：591 21985150 刊登中，483,395／使用約226坪（與前次相同）；同戶 21595066 也仍刊登；10/12 再查：21985150 仍為 483,395；使用者另給同戶 591 21812612（易信，483,395／255坪權狀）；⚠ 原「未含稅」依據 591 21595066 已下架，現存兩筆都沒寫稅別 | Y9: 實坪只有仲介口述；綠紅藍捷運距離未確認（概略座標推算松江南京約780m）；稅別依據（591 21595066「未含稅」）已下架，現存刊登未寫稅別 | Z9: 弘浥 張先生 0920-323-930；易信國際 王先生 0955-866-400 | AA9: 開啟 | AB9: 開啟地圖 | AC9: 待確認：實坪未揭露（權狀255.18坪） · 綠紅藍捷運距離未確認（最近 行天宮(橘) 188m）；已符合：月租50.8萬（45～55萬）
A10: S06 | B10: 八德大樓 7F（出租254.06坪） | C10: 待確認實坪 | D10: 中山 | E10: 八德路二段 | F10: 7F/12F | G10: 254.06 | I10: 381090 | J10: 381,090（信義刊登）；591 22053377 254坪 381,000 | K10: 41920 | L10: =IF(OR(I10="",K10=""),"管理費缺",I10+K10) -> 423010 | M10: =IF(OR(I10="",G10=""),"",I10/G10) -> 1500 | N10: =IF(H10="","未揭露",IF(H10>=0_條件與假設!$B$5,"✓","✗")) -> 未揭露 | O10: =IF(I10="","未提供",IF(I10<=0_條件與假設!$B$6,"≤45萬",IF(I10<=0_條件與假設!$B$7,"45～55萬","超過55萬"))) -> ≤45萬 | P10: 忠孝復興 | Q10: 藍 | R10: 620 | S10: 11 | T10: =IF(S10="","未確認",IF(S10<=0_條件與假設!$B$8,"✓",IF(S10<=16,"△ 11～16分","✗"))) -> △ 11～16分 | U10: 廁所新：與 S11 同棟同規格：廁所新裝修（信義 CZ05587 照片 H）、茶水間新（照片 G）。 | V10: 3年 | W10: 3個月 | X10: 9/30：信義 CZ05587 刊登中，381,090／出租254.06坪（與前次相同）；10/12 再查：CZ05587 仍為 381,090／254.06坪 | Y10: 出租部分實坪未揭露；稅別未寫 | Z10: 信義 林嘉君 0912-313-517 | AA10: 開啟 | AB10: 開啟地圖 | AC10: 待確認：實坪未揭露（權狀254.06坪） · 捷運忠孝復興(藍) 11分（>10分）；已符合：月租38.1萬
A11: N09 | B11: 長春路 8F（松江南京站） | C11: 待確認實坪 | D11: 中山 | E11: 長春路 | F11: 8F/12F | G11: 253 | I11: 480035 | J11: 480,035（591 22061922，稅別未寫） | L11: =IF(OR(I11="",K11=""),"管理費缺",I11+K11) -> 管理費缺 | M11: =IF(OR(I11="",G11=""),"",I11/G11) -> 1897.3715 | N11: =IF(H11="","未揭露",IF(H11>=0_條件與假設!$B$5,"✓","✗")) -> 未揭露 | O11: =IF(I11="","未提供",IF(I11<=0_條件與假設!$B$6,"≤45萬",IF(I11<=0_條件與假設!$B$7,"45～55萬","超過55萬"))) -> 45～55萬 | P11: 松江南京 | Q11: 綠 | R11: 310 | S11: 6 | T11: =IF(S11="","未確認",IF(S11<=0_條件與假設!$B$8,"✓",IF(S11<=16,"△ 11～16分","✗"))) -> ✓ | U11: 廁所無照片：591 共 4 張皆為辦公區（開放式天花、地毯），沒有拍廁所。需現勘。 | V11: 兩年 | W11: 面議 | X11: 9/30：591 22061922 刊登中，480,035／253坪（與前次相同）；10/12 再查：22061922 仍為 480,035／253坪 | Y11: 實坪未揭露；租金稅別未寫；管理費未提供；廁所需現勘 | Z11: 易信國際 王先生 0955-866-400 | AA11: 開啟 | AB11: 開啟地圖 | AC11: 待確認：實坪未揭露（權狀253坪）；已符合：月租48.0萬（45～55萬） · 松江南京(綠) 6分
A12: N27 | B12: 南京東路五段 3F（南京三民站） | C12: 待確認實坪 | D12: 松山 | E12: 南京東路五段 | F12: 3F/16F | G12: 243 | I12: 534754 | J12: 534,754（591 22061968，稅別未寫；若為未稅，含稅561,492將超過上限） | L12: =IF(OR(I12="",K12=""),"管理費缺",I12+K12) -> 管理費缺 | M12: =IF(OR(I12="",G12=""),"",I12/G12) -> 2200.6337 | N12: =IF(H12="","未揭露",IF(H12>=0_條件與假設!$B$5,"✓","✗")) -> 未揭露 | O12: =IF(I12="","未提供",IF(I12<=0_條件與假設!$B$6,"≤45萬",IF(I12<=0_條件與假設!$B$7,"45～55萬","超過55萬"))) -> 45～55萬 | P12: 南京三民 | Q12: 綠 | R12: 48 | S12: 1 | T12: =IF(S12="","未確認",IF(S12<=0_條件與假設!$B$8,"✓",IF(S12<=16,"△ 11～16分","✗"))) -> ✓ | U12: 廁所無照片：591 共 4 張（辦公區、外觀），沒有拍廁所。需現勘。 | V12: 兩年 | W12: 面議 | X12: 9/30：591 22061968 刊登中，534,754／243坪（與前次相同）；10/12 再查：22061968 仍為 534,754／243坪 | Y12: 實坪未揭露；稅別未寫（未稅則超過55萬）；廁所需現勘 | Z12: 易信國際 王先生 0955-866-400 | AA12: 開啟 | AB12: 開啟地圖 | AC12: 待確認：實坪未揭露（權狀243坪）；已符合：月租53.5萬（45～55萬） · 南京三民(綠) 1分
A13: D | B13: 敦化財經大樓 4F之1 | C13: 不符合 | D13: 松山 | E13: 敦化北路214號 | F13: 4F/11F(B2) | G13: 220.07 | H13: 207.21 | I13: 440140 | J13: 440,140 含稅（尚揚物調表）；591 同戶 386,839 稅別未寫 | K13: 48415 | L13: =IF(OR(I13="",K13=""),"管理費缺",I13+K13) -> 488555 | M13: =IF(OR(I13="",G13=""),"",I13/G13) -> 2000 | N13: =IF(H13="","未揭露",IF(H13>=0_條件與假設!$B$5,"✓","✗")) -> ✗ | O13: =IF(I13="","未提供",IF(I13<=0_條件與假設!$B$6,"≤45萬",IF(I13<=0_條件與假設!$B$7,"45～55萬","超過55萬"))) -> ≤45萬 | P13: 中山國中(棕) 404m（591寫明） | T13: =IF(S13="","未確認",IF(S13<=0_條件與假設!$B$8,"✓",IF(S13<=16,"△ 11～16分","✗"))) -> 未確認 | U13: 廁所在外：物調表註明「廁所在外」（公共廁所，非本戶專用）；尚揚照片大多為毛胚（天花拆除、管線外露），沒有拍廁所；591 21711753 共 11 張為大樓外觀、大廳（石材）與周邊，也沒有室內與廁所照片。 | V13: 2年 | W13: 3個月 | X13: 10/12：591 21711753 刊登中，446,480（含稅）／權狀220.07、主建＋附屬207.21 | Y13: 591 與物調表租金／管理費不同（446,480 vs 440,140；47,840 vs 48,415） | Z13: 尚揚國際 張正修 0937-519-365 | AA13: 開啟 | AB13: 開啟地圖 | AC13: 不符：實坪207.21（差12.8坪）
A14: N17 | B14: 松哖大樓 2F | C14: 不符合 | D14: 中山 | E14: 民生東路二段161號＋163號2樓 | F14: 2F/12F(B1) | G14: 227.15 | H14: 198.26 | I14: 500000 | J14: 500,000 含稅（尚揚物調表）；591 同樓層 439,450～500,000 多筆 | K14: 40000 | L14: =IF(OR(I14="",K14=""),"管理費缺",I14+K14) -> 540000 | M14: =IF(OR(I14="",G14=""),"",I14/G14) -> 2201.1886 | N14: =IF(H14="","未揭露",IF(H14>=0_條件與假設!$B$5,"✓","✗")) -> ✗ | O14: =IF(I14="","未提供",IF(I14<=0_條件與假設!$B$6,"≤45萬",IF(I14<=0_條件與假設!$B$7,"45～55萬","超過55萬"))) -> 45～55萬 | P14: 行天宮(橘) 約185～299m | T14: =IF(S14="","未確認",IF(S14<=0_條件與假設!$B$8,"✓",IF(S14<=16,"△ 11～16分","✗"))) -> 未確認 | U14: 廁所無照片：尚揚照片為辦公區（水泥地坪、部分天花拆），沒有拍廁所；591 20941554 共 10 張也都是空室（天花部分拆除），沒有廁所。 | V14: 2年 | W14: 3個月 | X14: 10/12：591 20941554 刊登中，439,450／235.73坪 | Z14: 尚揚 劉品汯 0901-407-026 | AA14: 開啟 | AB14: 開啟地圖 | AC14: 不符：實坪198.26（差21.7坪）
A15: N34 | B15: 民權西路 5F（民權西路站） | C15: 不符合 | D15: 大同 | E15: 民權西路 | F15: 5F/13F | G15: 303 | I15: 450000 | J15: 450,000（591 11580037，稅別未寫） | L15: =IF(OR(I15="",K15=""),"管理費缺",I15+K15) -> 管理費缺 | M15: =IF(OR(I15="",G15=""),"",I15/G15) -> 1485.1485 | N15: =IF(H15="","未揭露",IF(H15>=0_條件與假設!$B$5,"✓","✗")) -> 未揭露 | O15: =IF(I15="","未提供",IF(I15<=0_條件與假設!$B$6,"≤45萬",IF(I15<=0_條件與假設!$B$7,"45～55萬","超過55萬"))) -> ≤45萬 | P15: 民權西路 | Q15: 紅 | R15: 164 | S15: 3 | T15: =IF(S15="","未確認",IF(S15<=0_條件與假設!$B$8,"✓",IF(S15<=16,"△ 11～16分","✗"))) -> ✓ | U15: 廁所無照片：591 11580037 共 12 張為現有裝潢（木紋地板、玻璃隔間會議室、茶水區），沒有拍廁所；照片上傳於 2021/09，現況需現勘。 | V15: 兩年 | W15: 2個月 | X15: 10/12：591 11580037 刊登中，450,000／303坪（含公設） | Y15: 大同區（不在五區內）；實坪未揭露；租金稅別未寫；管理費未提供 | Z15: 住商 林玉蘋 0952-060-901 | AA15: 開啟 | AB15: 開啟地圖 | AC15: 不符：非指定行政區
A16: N30 | B16: 敦化南路二段 15F（信義安和站） | C16: 不符合 | D16: 大安 | E16: 敦化南路二段 | F16: 15F/27F | G16: 204 | I16: 469200 | J16: 469,200（591 22062144，稅別未寫） | L16: =IF(OR(I16="",K16=""),"管理費缺",I16+K16) -> 管理費缺 | M16: =IF(OR(I16="",G16=""),"",I16/G16) -> 2300 | N16: =IF(H16="","未揭露",IF(H16>=0_條件與假設!$B$5,"✓","✗")) -> 未揭露 | O16: =IF(I16="","未提供",IF(I16<=0_條件與假設!$B$6,"≤45萬",IF(I16<=0_條件與假設!$B$7,"45～55萬","超過55萬"))) -> 45～55萬 | P16: 信義安和 | Q16: 紅 | R16: 760 | S16: 13 | T16: =IF(S16="","未確認",IF(S16<=0_條件與假設!$B$8,"✓",IF(S16<=16,"△ 11～16分","✗"))) -> △ 11～16分 | U16: 廁所無照片：591 22062144 共 9 張為空室（木紋地板、開放式天花）＋茶水間（照片 9，新），沒有拍廁所。 | V16: 3年 | W16: 面議 | X16: 10/12：591 22062144 刊登中，469,200／204坪（權狀） | Y16: 權狀僅204坪；租金稅別未寫；管理費未提供 | Z16: 易信國際 王先生 0955-866-400 | AA16: 開啟 | AB16: 開啟地圖 | AC16: 不符：權狀僅204坪（實坪必低於220）
A17: N31 | B17: 健康路 8F（南京三民／小巨蛋站） | C17: 不符合 | D17: 松山 | E17: 健康路 | F17: 8F/12F | G17: 195 | I17: 470925 | J17: 448,500 未稅（591 17979949 內文「此租金為未稅金額」，2,300元/坪）→ 含稅 470,925 | L17: =IF(OR(I17="",K17=""),"管理費缺",I17+K17) -> 管理費缺 | M17: =IF(OR(I17="",G17=""),"",I17/G17) -> 2415 | N17: =IF(H17="","未揭露",IF(H17>=0_條件與假設!$B$5,"✓","✗")) -> 未揭露 | O17: =IF(I17="","未提供",IF(I17<=0_條件與假設!$B$6,"≤45萬",IF(I17<=0_條件與假設!$B$7,"45～55萬","超過55萬"))) -> 45～55萬 | P17: 台北小巨蛋 | Q17: 綠 | R17: 180 | S17: 3 | T17: =IF(S17="","未確認",IF(S17<=0_條件與假設!$B$8,"✓",IF(S17<=16,"△ 11～16分","✗"))) -> ✓ | U17: 廁所無照片：591 17979949 共 15 張為空室（高架地板、地毯已拆）＋茶水間（照片 15），沒有拍廁所；刊登設備寫「公共衛生間」；照片上傳於 2024/06。 | V17: 3年 | W17: 面議 | X17: 10/12：591 17979949 刊登中，448,500（未稅）／195坪 | Y17: 刊登195坪；坪數性質未說明；管理費未提供 | Z17: 尚揚 陳先生 0906-118-677 | AA17: 開啟 | AB17: 開啟地圖 | AC17: 不符：591 刊登195坪（未說明權狀或使用坪數，任一種都低於220）
A18: N32 | B18: 南京東路三段 9F（南京復興站） | C18: 不符合 | D18: 中山 | E18: 南京東路三段 | F18: 9F/14F | G18: 209.16 | I18: 501984 | J18: 501,984 含稅（591 21423260 內文「此租金為含稅金額」，2,400元/坪） | L18: =IF(OR(I18="",K18=""),"管理費缺",I18+K18) -> 管理費缺 | M18: =IF(OR(I18="",G18=""),"",I18/G18) -> 2400 | N18: =IF(H18="","未揭露",IF(H18>=0_條件與假設!$B$5,"✓","✗")) -> 未揭露 | O18: =IF(I18="","未提供",IF(I18<=0_條件與假設!$B$6,"≤45萬",IF(I18<=0_條件與假設!$B$7,"45～55萬","超過55萬"))) -> 45～55萬 | P18: 南京復興 | Q18: 綠 | R18: 175 | S18: 3 | T18: =IF(S18="","未確認",IF(S18<=0_條件與假設!$B$8,"✓",IF(S18<=16,"△ 11～16分","✗"))) -> ✓ | U18: 廁所無照片：591 21423260 共 15 張為現況辦公室（目前有人使用：開放式天花、玻璃會議室、茶水間、哺乳室），沒有拍廁所；刊登設備寫「公共衛生間」。 | V18: 3年 | W18: 面議 | X18: 10/12：591 21423260 刊登中，501,984（含稅）／209.16坪（權狀） | Y18: 權狀僅209坪；管理費未提供 | Z18: 尚揚 陳先生 0906-118-677 | AA18: 開啟 | AB18: 開啟地圖 | AC18: 不符：權狀僅209.16坪（實坪必低於220）
A19: N29 | B19: 健康路 3F（台北小巨蛋站） | C19: 不符合 | D19: 松山 | E19: 健康路 | F19: 3F/12F | G19: 221 | I19: 508300 | J19: 508,300（591 20903777，稅別未寫） | L19: =IF(OR(I19="",K19=""),"管理費缺",I19+K19) -> 管理費缺 | M19: =IF(OR(I19="",G19=""),"",I19/G19) -> 2300 | N19: =IF(H19="","未揭露",IF(H19>=0_條件與假設!$B$5,"✓","✗")) -> 未揭露 | O19: =IF(I19="","未提供",IF(I19<=0_條件與假設!$B$6,"≤45萬",IF(I19<=0_條件與假設!$B$7,"45～55萬","超過55萬"))) -> 45～55萬 | P19: 台北小巨蛋 | Q19: 綠 | R19: 94 | S19: 2 | T19: =IF(S19="","未確認",IF(S19<=0_條件與假設!$B$8,"✓",IF(S19<=16,"△ 11～16分","✗"))) -> ✓ | U19: 廁所無照片：591 20903777 共 4 張為空室（新木紋地板、新天花燈具），沒有拍廁所；刊登設備寫「獨立衛生間」。 | V19: 兩年 | W19: 面議 | X19: 10/12：591 20903777 刊登中，508,300／221坪（權狀） | Y19: 權狀僅221坪；實坪未揭露；租金稅別未寫；管理費未提供 | Z19: 591 刊登人（專案經理）0977-222-827 | AA19: 開啟 | AB19: 開啟地圖 | AC19: 不符：權狀221坪，公設比需≤0.5%才達220（實坪未揭露）
A20: N33 | B20: 菸廠路 8F（國父紀念館站・松菸旁） | C20: 不符合 | D20: 信義 | E20: 菸廠路 | F20: 8F/14F | G20: 196 | I20: 578621 | J20: 551,068 未稅（591 22162790 內文「此租金未含加值型營業稅5%」）→ 含稅 578,621 | L20: =IF(OR(I20="",K20=""),"管理費缺",I20+K20) -> 管理費缺 | M20: =IF(OR(I20="",G20=""),"",I20/G20) -> 2952.148 | N20: =IF(H20="","未揭露",IF(H20>=0_條件與假設!$B$5,"✓","✗")) -> 未揭露 | O20: =IF(I20="","未提供",IF(I20<=0_條件與假設!$B$6,"≤45萬",IF(I20<=0_條件與假設!$B$7,"45～55萬","超過55萬"))) -> 超過55萬 | P20: 國父紀念館 | Q20: 藍 | R20: 274 | S20: 5 | T20: =IF(S20="","未確認",IF(S20<=0_條件與假設!$B$8,"✓",IF(S20<=16,"△ 11～16分","✗"))) -> ✓ | U20: 廁所無照片：591 22162790 共 7 張為空室（地毯舊、有磨損，面松菸／大巨蛋），沒有拍廁所。 | V20: 一年 | W20: 面議 | X20: 10/12：591 22162790 刊登中，551,068（未稅）／196坪 | Y20: 刊登僅196坪；含稅超過55萬；管理費未提供 | Z20: 東家國際 蔡泳翰 0912-816-677 | AA20: 開啟 | AB20: 開啟地圖 | AC20: 不符：權狀僅196坪（實坪必低於220）；月租578,621超過55萬
A21: J17 | B21: 市民大道3段近復興南路 8F 257坪 | C21: 不符合 | D21: 大安 | E21: 市民大道3段近復興南路 | F21: 8F | G21: 257 | I21: 588000 | J21: 588,000（未稅×1.05） | L21: =IF(OR(I21="",K21=""),"管理費缺",I21+K21) -> 管理費缺 | M21: =IF(OR(I21="",G21=""),"",I21/G21) -> 2287.9377 | N21: =IF(H21="","未揭露",IF(H21>=0_條件與假設!$B$5,"✓","✗")) -> 未揭露 | O21: =IF(I21="","未提供",IF(I21<=0_條件與假設!$B$6,"≤45萬",IF(I21<=0_條件與假設!$B$7,"45～55萬","超過55萬"))) -> 超過55萬 | P21: 忠孝復興 | Q21: 藍 | R21: 370 | S21: 7 | T21: =IF(S21="","未確認",IF(S21<=0_條件與假設!$B$8,"✓",IF(S21<=16,"△ 11～16分","✗"))) -> ✓ | U21: 廁所無照片：591 22061936 共 3 張（接待櫃台、會客區、會議室，高檔裝潢），沒有拍廁所。 | V21: — | W21: 3個月 | X21: 10/12：591 22061936 刊登中，533,333（稅別未寫）／257坪（權狀） | Y21: 591 533,333 稅別未寫（若含稅則≤55萬，需確認）；同棟仲介口述使用約171坪 | Z21: 傑森愛華 張先生 0931-330823 | AA21: 開啟 | AB21: 開啟地圖 | AC21: 不符：月租588,000超過55萬
A22: N28 | B22: 民生東路三段 8F（中山國中站） | C22: 不符合 | D22: 中山 | E22: 民生東路三段 | F22: 8F/16F | G22: 254.53 | I22: 614678 | J22: 585,408 未稅（591 22129776 內文「租金為未稅金額」）→ 含稅 614,678 | L22: =IF(OR(I22="",K22=""),"管理費缺",I22+K22) -> 管理費缺 | M22: =IF(OR(I22="",G22=""),"",I22/G22) -> 2414.9531 | N22: =IF(H22="","未揭露",IF(H22>=0_條件與假設!$B$5,"✓","✗")) -> 未揭露 | O22: =IF(I22="","未提供",IF(I22<=0_條件與假設!$B$6,"≤45萬",IF(I22<=0_條件與假設!$B$7,"45～55萬","超過55萬"))) -> 超過55萬 | P22: 南京復興 | Q22: 綠 | R22: 1070 | S22: 18 | T22: =IF(S22="","未確認",IF(S22<=0_條件與假設!$B$8,"✓",IF(S22<=16,"△ 11～16分","✗"))) -> ✗ | U22: 廁所無照片：591 22129776 共 12 張皆為辦公區（現成新式裝潢、目前有人使用：會議室、茶水吧、置物櫃），沒有拍廁所。 | V22: 一年 | W22: 面議 | X22: 10/12：591 22129776 刊登中，585,408（未稅）／254.53坪 | Y22: 含稅超過55萬；實坪未揭露；管理費未提供；綠紅藍捷運步行約18分（概略） | Z22: 同陽商仲 房先生 0978-751-212 | AA22: 開啟 | AB22: 開啟地圖 | AC22: 不符：月租614,678超過55萬；捷運南京復興(綠) 18分太遠

Sheet A_總表
A1: 分級 | B1: 排序 | C1: 案號 | D1: 案名 | E1: 行政區 | F1: 地址 | G1: 樓層 | H1: 權狀坪 | I1: 實坪 (主+附) | J1: 實坪來源 | K1: 月租(含稅) | L1: 租金原文／稅別 | M1: 管理費(月) | N1: 月總成本(公式) 管理費缺＝只含租金 | O1: 每實坪月成本 (公式) | P1: 實坪≥門檻 (公式) | Q1: 租金級距 (公式) | R1: 最近綠紅藍站 | S1: 路線 | T1: 距離(m) | U1: 步行(分) | V1: 捷運判定 (公式) | W1: 判定說明 | X1: 缺漏／待確認 | Y1: 屋況／廁所（照片判讀） | Z1: 屋齡 | AA1: 車位 | AB1: 來源 | AC1: 聯絡人 | AD1: 連結 | AE1: 地圖定位依據 | AF1: Google 地圖
A2: 第一優先 | B2: 1 | C2: S05 | D2: 建國北路二段 10F（大辦公室＋大倉儲） | E2: 中山 | F2: 建國北路二段 | G2: 10F/12F | H2: 278.04 | I2: 262.5 | J2: 信義房屋物件頁：主建物246.00＋附屬16.50（共有15.54） | K2: 388500 | L2: 388,500（信義房屋刊登） | M2: 37500 | N2: =IF(K2="","",K2+N(M2)) -> 426000 | O2: =IF(OR(I2="",N2=""),"",N2/I2) -> 1622.8571 | P2: =IF(I2="","未揭露",IF(I2>=0_條件與假設!$B$5,"✓","✗")) -> ✓ | Q2: =IF(K2="","未提供",IF(K2<=0_條件與假設!$B$6,"≤45萬",IF(K2<=0_條件與假設!$B$7,"45～55萬","超過55萬"))) -> ≤45萬 | R2: 松江南京 | S2: 綠 | T2: 530 | U2: 9 | V2: =IF(U2="","未確認",IF(U2<=0_條件與假設!$B$8,"✓",IF(U2<=16,"△ 11～16分","✗"))) -> ✓ | W2: 四項全符合：實坪262.5 · 月租38.9萬 · 松江南京(綠) 9分 | X2: 租金稅別未寫；廁所老舊需整修 | Y2: 廁所老舊：廁所為舊式裝修（信義房屋物件照片 M、N）：立柱式洗手台、舊式隔間、天花板老式排風扇與日光燈格柵；辦公區地毯有污漬、部分天花板板材已拆（照片 C、D、G）；電梯廳已翻新（照片 K、L）；茶水間小（照片 I、J）。建議把廁所整修列入議價，或要求房東交屋前整修。 | Z2: 屋齡41.7年 | AA2: 無；平面車位可另租5,000 | AB2: 信義房屋 C905199（2026/07/28更新） | AC2: 張聰仁 信義房屋投資二部 0939-738-856 | AD2: 信義全球物件頁（16張照片） | AE2: 物件頁座標：信義全球物件座標（25.055616, 121.536479） | AF2: 開啟地圖
A3: 第二優先 | B3: 2 | C3: N04 | D3: 信義大樓 10F | E3: 信義 | F3: 松仁路（信義大樓） | G3: 10F/23F | H3: 330.22 | I3: 300.43 | J3: 同一戶信義房屋 C904200：主254.24＋附46.19（591 刊登「300坪」與此相符） | K3: 480000 | L3: 480,000（591 21537848，稅別未寫）；同戶信義房屋刊登577,885 | M3: 49533 | N3: =IF(K3="","",K3+N(M3)) -> 529533 | O3: =IF(OR(I3="",N3=""),"",N3/I3) -> 1762.5836 | P3: =IF(I3="","未揭露",IF(I3>=0_條件與假設!$B$5,"✓","✗")) -> ✓ | Q3: =IF(K3="","未提供",IF(K3<=0_條件與假設!$B$6,"≤45萬",IF(K3<=0_條件與假設!$B$7,"45～55萬","超過55萬"))) -> 45～55萬 | R3: 象山 | S3: 紅 | T3: 950 | U3: 16 | V3: =IF(U3="","未確認",IF(U3<=0_條件與假設!$B$8,"✓",IF(U3<=16,"△ 11～16分","✗"))) -> △ 11～16分 | W3: 坪數符合；實坪300.43 · 月租48.0萬（45～55萬） · 捷運象山(紅) 16分（>10分） | X3: 591 48萬刊登已下架（9/30），現存刊登為信義 577,885（超過55萬）；租金稅別未寫；兩方報價不同 | Y3: 廁所新：廁所為新裝修（信義房屋 C904200 照片 C：檯面式洗手台、木紋隔間）；辦公區天花為開放式未封板。 | Z3: 屋齡約29年 | AA3: 591：平面式 | AB3: 591 21537848（傑森愛華 張先生）；信義房屋 C904200 | AC3: 傑森愛華 張先生 0931-330-823 | AD3: 信義全球 10F（面積分項） | AE3: 物件頁座標：同信義大樓座標（25.024307, 121.569847） | AF3: 開啟地圖
A4: 第二優先 | B4: 3 | C4: C | D4: 旭寶大樓 5F | E4: 松山 | F4: 敦化南路一段25號 | G4: 5F/12F(B2) | H4: 282.06 | I4: 255.38 | J4: 尚揚物調表：實用坪255.38 | K4: 472500 | L4: 472,500 含稅（尚揚物調表）；591 21530071 刊登450,000（=未稅，×1.05即472,500） | M4: 33847 | N4: =IF(K4="","",K4+N(M4)) -> 506347 | O4: =IF(OR(I4="",N4=""),"",N4/I4) -> 1982.7199 | P4: =IF(I4="","未揭露",IF(I4>=0_條件與假設!$B$5,"✓","✗")) -> ✓ | Q4: =IF(K4="","未提供",IF(K4<=0_條件與假設!$B$6,"≤45萬",IF(K4<=0_條件與假設!$B$7,"45～55萬","超過55萬"))) -> 45～55萬 | R4: 忠孝敦化 | S4: 藍 | T4: 570 | U4: 10 | V4: =IF(U4="","未確認",IF(U4<=0_條件與假設!$B$8,"✓",IF(U4<=16,"△ 11～16分","✗"))) -> ✓ | W4: 坪數符合；實坪255.38 · 月租47.2萬（45～55萬） · 忠孝敦化(藍) 10分 | X4: 只能租4年（之後都更）；廁所老舊需整修 | Y4: 廁所老舊：廁所為舊式裝修（591 21530071 照片 9、10）：藍色磁磚地坪、藍色立柱式洗手台、舊式小便斗與隔間、舊天花板；茶水間為木紋新作（照片 11）。建議把廁所整修列入議價。 | Z4: 屋齡約43年（1983/12竣工，好房網） | AA4: 機械車位×6（租金內含） | AB4: 尚揚國際物調表；591 21530071（房仲提供）；591 21524253「敦南綠景」5F 250.97坪 45萬含6車位（21530071 標題同稱「敦南綠景」→ 同戶） | AC4: 尚揚 王智平 0917-154-083；591 呂育瑄 0919-219-331 | AD4: 大樓照片（好房網19張） | AE4: 門牌定位：Google地圖：敦化南路一段25號（25.0464096, 121.5494252） | AF4: 開啟地圖
A5: 第二優先 | B5: 4 | C5: N02 | D5: 廣成大廈 4F | E5: 中正 | F5: 延平南路189號4樓～之5 | G5: 4F/7F(B2) | H5: 326.85 | I5: 253.54 | J5: 尚揚物調表：主建物＋附屬建物253.54 | K5: 491000 | L5: 491,000（尚揚物調表標示「含稅」；傑森愛華清單同價但標「未稅」；591 21779044 標491,000含管理費；591 20971276 標491,000、管理費另計31,053） | M5: 31053 | N5: =IF(K5="","",K5+N(M5)) -> 522053 | O5: =IF(OR(I5="",N5=""),"",N5/I5) -> 2059.0558 | P5: =IF(I5="","未揭露",IF(I5>=0_條件與假設!$B$5,"✓","✗")) -> ✓ | Q5: =IF(K5="","未提供",IF(K5<=0_條件與假設!$B$6,"≤45萬",IF(K5<=0_條件與假設!$B$7,"45～55萬","超過55萬"))) -> 45～55萬 | R5: 小南門 | S5: 綠 | T5: 380 | U5: 7 | V5: =IF(U5="","未確認",IF(U5<=0_條件與假設!$B$8,"✓",IF(U5<=16,"△ 11～16分","✗"))) -> ✓ | W5: 坪數符合；實坪253.54 · 月租49.1萬（45～55萬） · 小南門(綠) 7分 | X5: 租金是否含稅、是否含管理費：物調表／傑森愛華／591 三方說法不同，需書面確認；廁所需現勘 | Y5: 廁所無照片：尚揚照片、591 21779044（3 張：大廳、空室）、傑森愛華清單照片都沒有拍廁所；辦公區為開放空間、水泥地坪需整理。需現勘。 | Z5: 民國70/1/5竣工（屋齡約45年） | AA5: 固定車位7,000(含稅)／非固定5,000(含稅) | AB5: 尚揚物調表（陳威翰）；591 21779044、20971276（葛林威 林小姐，326.87坪 4F/7F 491,000＋管理費31,053）、22009979；傑森愛華 2026/9/23清單第3頁 | AC5: 尚揚 陳威翰 0906-118-677；591 楊小姐 02-27415343#36；591 葛林威 林小姐 0984-002-297 | AD5: 591 物件頁 | AE5: 門牌定位：Google地圖：延平南路189號（25.0337995, 121.5075571） | AF5: 開啟地圖
A6: 第二優先 | B6: 5 | C6: S12 | D6: 全球人壽信義大樓 21F | E6: 信義 | F6: 松仁路277號21樓 | G6: 21F/23F(B4) | H6: 265.82 | I6: 241.8 | J6: 尚揚物調表：主建物＋附屬241.8；信義房屋 C904707：主204.94＋附36.86＝241.80 | K6: 502400 | L6: 502,400 含稅（尚揚物調表）；信義房屋刊登544,931 | M6: 39873 | N6: =IF(K6="","",K6+N(M6)) -> 542273 | O6: =IF(OR(I6="",N6=""),"",N6/I6) -> 2242.651 | P6: =IF(I6="","未揭露",IF(I6>=0_條件與假設!$B$5,"✓","✗")) -> ✓ | Q6: =IF(K6="","未提供",IF(K6<=0_條件與假設!$B$6,"≤45萬",IF(K6<=0_條件與假設!$B$7,"45～55萬","超過55萬"))) -> 45～55萬 | R6: 象山 | S6: 紅 | T6: 950 | U6: 16 | V6: =IF(U6="","未確認",IF(U6<=0_條件與假設!$B$8,"✓",IF(U6<=16,"△ 11～16分","✗"))) -> △ 11～16分 | W6: 坪數符合；實坪241.8 · 月租50.2萬（45～55萬） · 捷運象山(紅) 16分（>10分） | Y6: 廁所新：廁所、茶水間為新裝修（尚揚照片：石材牆面、木紋隔間、檯面式洗手台）；地毯、天花完整。 | Z6: 民國86/5/25竣工（屋齡約29年） | AA6: 物調表未載；信義頁：無 | AB6: 尚揚物調表（劉于上）；信義房屋 C904707 | AC6: 尚揚 劉于上 0938-259-324；信義 許雅傑 0966-513-725 | AD6: 信義全球物件頁 | AE6: 物件頁座標：信義全球物件座標（25.024307, 121.569847） | AF6: 開啟地圖
A7: 第二優先 | B7: 6 | C7: N01 | D7: 南海開發大樓 5F | E7: 中正 | F7: 南海路20號5樓 | G7: 5F/10F(B1) | H7: 260.98 | I7: 228.34 | J7: 尚揚物調表：主建物＋附屬建物228.34 | K7: 465849 | L7: 465,849 含稅（尚揚物調表）；591 22010357 刊登443,666（×1.05=465,849，即未稅價）；傑森愛華清單 443,000 未稅 | N7: =IF(K7="","",K7+N(M7)) -> 465849 | O7: =IF(OR(I7="",N7=""),"",N7/I7) -> 2040.155 | P7: =IF(I7="","未揭露",IF(I7>=0_條件與假設!$B$5,"✓","✗")) -> ✓ | Q7: =IF(K7="","未提供",IF(K7<=0_條件與假設!$B$6,"≤45萬",IF(K7<=0_條件與假設!$B$7,"45～55萬","超過55萬"))) -> 45～55萬 | R7: 中正紀念堂 | S7: 紅綠 | T7: 150 | U7: 3 | V7: =IF(U7="","未確認",IF(U7<=0_條件與假設!$B$8,"✓",IF(U7<=16,"△ 11～16分","✗"))) -> ✓ | W7: 坪數符合；實坪228.34 · 月租46.6萬（45～55萬） · 中正紀念堂(紅綠) 3分 | X7: 管理費只有區間（2.5萬～3萬），無確切金額；廁所需現勘 | Y7: 廁所無照片：尚揚照片與 591 22010357（僅 1 張外觀）都沒有拍廁所；辦公區為亮面地坪、天花完整。需現勘。 | Z7: 民國77/9/22竣工（屋齡約38年） | AA7: 附坡平車位2個（591：含車位） | AB7: 尚揚物調表（陳威翰）；591 22010357、21589109；傑森愛華 2026/9/23清單第1頁 | AC7: 尚揚 陳威翰 0906-118-677；兆淇 鄭先生 0960-539-161；傑森愛華 張先生 0931-330823 | AD7: 591 物件頁 | AE7: 門牌定位：Google地圖：南海路20號（25.0324406, 121.5169915） | AF7: 開啟地圖
A8: 待確認實坪 | B8: 7 | C8: N05 | D8: 信義大樓 8F | E8: 信義 | F8: 松仁路（信義區） | G8: 8F | H8: 331 | J8: 8F 本身未揭露；同棟5F/9F 實坪300.54／300.44（信義房屋） | K8: 538703 | L8: 513,050 未稅（@1,550）→ 含稅 538,703 | N8: =IF(K8="","",K8+N(M8)) -> 538703 | O8: =IF(OR(I8="",N8=""),"",N8/I8) | P8: =IF(I8="","未揭露",IF(I8>=0_條件與假設!$B$5,"✓","✗")) -> 未揭露 | Q8: =IF(K8="","未提供",IF(K8<=0_條件與假設!$B$6,"≤45萬",IF(K8<=0_條件與假設!$B$7,"45～55萬","超過55萬"))) -> 45～55萬 | R8: 象山 | S8: 紅 | T8: 950 | U8: 16 | V8: =IF(U8="","未確認",IF(U8<=0_條件與假設!$B$8,"✓",IF(U8<=16,"△ 11～16分","✗"))) -> △ 11～16分 | W8: 待確認：實坪未揭露（權狀331坪） · 捷運象山(紅) 16分（>10分）；已符合：月租53.9萬（45～55萬） | X8: 實坪未揭露；管理費未提供；廁所需現勘 | Y8: 8F未拍廁所：8F 本身沒有室內照片（傑森愛華 3 張皆外觀）；同棟 10F、21F 廁所為新裝修，8F 需現勘確認。 | Z8: 屋齡約29年 | AA8: 未提供 | AB8: 傑森愛華 2026/9/23清單第3頁 | AC8: 傑森愛華 張先生 0931-330823 | AD8: 傑森愛華清單 第3頁 | AE8: 物件頁座標：同信義大樓座標（25.024307, 121.569847） | AF8: 開啟地圖
A9: 待確認實坪 | B9: 8 | C9: N08 | D9: 松江路 3F（松江南京站） | E9: 中山 | F9: 松江路 | G9: 3F/12F | H9: 302 | J9: 591 原文「刊登坪數、權狀面積依地政機關登記為準」 | K9: 540837 | L9: 515,083 未含營業稅（591 21635155）→ 含稅 540,837 | N9: =IF(K9="","",K9+N(M9)) -> 540837 | O9: =IF(OR(I9="",N9=""),"",N9/I9) | P9: =IF(I9="","未揭露",IF(I9>=0_條件與假設!$B$5,"✓","✗")) -> 未揭露 | Q9: =IF(K9="","未提供",IF(K9<=0_條件與假設!$B$6,"≤45萬",IF(K9<=0_條件與假設!$B$7,"45～55萬","超過55萬"))) -> 45～55萬 | R9: 松江南京 | S9: 綠 | T9: 156 | U9: 3 | V9: =IF(U9="","未確認",IF(U9<=0_條件與假設!$B$8,"✓",IF(U9<=16,"△ 11～16分","✗"))) -> ✓ | W9: 待確認：實坪未揭露（權狀302坪）；已符合：月租54.1萬（45～55萬） · 松江南京(綠) 3分 | X9: 實坪未揭露；管理費未提供；廁所需現勘 | Y9: 廁所無照片：591 只有 1 張照片（捷運出口），室內與廁所都沒有拍。需現勘。 | Z9: 未提供 | AA9: 未提供 | AB9: 591 21635155（東家）、22017413（兆淇 鄭先生，302.99坪、515,083、1,700元/坪）、21888124、21548435 | AC9: 東家國際 蔡泳翰 0912-816-677；兆淇 鄭先生 0960-539-161 | AD9: 591 物件頁 | AE9: 概略位置：591 21635155 物件頁地圖座標（門牌未揭露，591 標點可能為概略位置）（25.0533328, 121.5334926） | AF9: 開啟地圖
A10: 待確認實坪 | B10: 9 | C10: S11 | D10: 八德大樓 5F（出租285.67坪） | E10: 中山 | F10: 八德路二段 | G10: 5F/12F | H10: 285.67 | J10: 信義 CZ05585：整筆權狀577.14、主322.97＋附38.67（整筆），出租285.67坪部分的實坪未寫 | K10: 428505 | L10: 428,505（信義刊登）；591 21804249 285坪 427,500（1,500/坪） | M10: 47136 | N10: =IF(K10="","",K10+N(M10)) -> 475641 | O10: =IF(OR(I10="",N10=""),"",N10/I10) | P10: =IF(I10="","未揭露",IF(I10>=0_條件與假設!$B$5,"✓","✗")) -> 未揭露 | Q10: =IF(K10="","未提供",IF(K10<=0_條件與假設!$B$6,"≤45萬",IF(K10<=0_條件與假設!$B$7,"45～55萬","超過55萬"))) -> ≤45萬 | R10: 忠孝復興 | S10: 藍 | T10: 620 | U10: 11 | V10: =IF(U10="","未確認",IF(U10<=0_條件與假設!$B$8,"✓",IF(U10<=16,"△ 11～16分","✗"))) -> △ 11～16分 | W10: 待確認：實坪未揭露（權狀285.67坪） · 捷運忠孝復興(藍) 11分（>10分）；已符合：月租42.9萬 | X10: 出租部分實坪未揭露；稅別未寫 | Y10: 廁所新：廁所新裝修（信義 CZ05585 照片 D、G：石材檯面、新式小便斗、木紋隔間）；茶水間新（照片 J）；電梯廳石材。 | Z10: 屋齡30.1年 | AA10: 無 | AB10: 信義房屋 CZ05585；591 20991086、21804249 | AC10: 信義 林嘉君 0912-313-517 | AD10: 信義全球物件頁 | AE10: 物件頁座標：信義全球物件座標（25.046292, 121.540346） | AF10: 開啟地圖
A11: 待確認實坪 | B11: 10 | C11: N10 | D11: 光復北路11巷 2F（南京三民站） | E11: 松山 | F11: 光復北路11巷 | G11: 2F/14F | H11: 283 | J11: 591 原文「廣告坪數為權狀坪數」 | K11: 534870 | L11: 509,400 未稅（591 22062249、傑森愛華清單第2頁）→ 含稅 534,870 | N11: =IF(K11="","",K11+N(M11)) -> 534870 | O11: =IF(OR(I11="",N11=""),"",N11/I11) | P11: =IF(I11="","未揭露",IF(I11>=0_條件與假設!$B$5,"✓","✗")) -> 未揭露 | Q11: =IF(K11="","未提供",IF(K11<=0_條件與假設!$B$6,"≤45萬",IF(K11<=0_條件與假設!$B$7,"45～55萬","超過55萬"))) -> 45～55萬 | R11: 南京三民 | S11: 綠 | T11: 88 | U11: 2 | V11: =IF(U11="","未確認",IF(U11<=0_條件與假設!$B$8,"✓",IF(U11<=16,"△ 11～16分","✗"))) -> ✓ | W11: 待確認：實坪未揭露（權狀283坪）；已符合：月租53.5萬（45～55萬） · 南京三民(綠) 2分 | X11: 實坪未揭露；大樓名稱為推定；管理費未提供；廁所需現勘 | Y11: 廁所無照片：591 只有 2 張（空室、捷運站），沒有拍廁所。需現勘。 | Z11: 未提供 | AA11: 未提供（傑森愛華：停車方便） | AB11: 591 22062249（易信 王先生）；傑森愛華 2026/9/23清單第2頁 | AC11: 易信國際 王先生 0955-866-400；傑森愛華 張先生 0931-330823 | AD11: 591 物件頁 | AE11: 概略位置：591 22062249 物件頁地圖座標（門牌未揭露，591 標點可能為概略位置）（25.0508017, 121.5633299） | AF11: 開啟地圖
A12: 待確認實坪 | B12: 11 | C12: N11 | D12: 旭寶大樓 4F | E12: 松山 | F12: 敦化南路一段25號 | G12: 4F/12F | H12: 282.06 | J12: 591 原文「廣告顯示使用面積為含公設面積」；同棟5F 實用255.38（尚揚） | K12: 532980 | L12: 507,600 未稅（傑森愛華清單第2頁）；591 21788157 507,708 未含稅 → 含稅約533,000 | N12: =IF(K12="","",K12+N(M12)) -> 532980 | O12: =IF(OR(I12="",N12=""),"",N12/I12) | P12: =IF(I12="","未揭露",IF(I12>=0_條件與假設!$B$5,"✓","✗")) -> 未揭露 | Q12: =IF(K12="","未提供",IF(K12<=0_條件與假設!$B$6,"≤45萬",IF(K12<=0_條件與假設!$B$7,"45～55萬","超過55萬"))) -> 45～55萬 | R12: 忠孝敦化 | S12: 藍 | T12: 570 | U12: 10 | V12: =IF(U12="","未確認",IF(U12<=0_條件與假設!$B$8,"✓",IF(U12<=16,"△ 11～16分","✗"))) -> ✓ | W12: 待確認：實坪未揭露（權狀282.06坪）；已符合：月租53.3萬（45～55萬） · 忠孝敦化(藍) 10分 | X12: 實坪未揭露；管理費未提供；廁所需現勘 | Y12: 廁所無照片：591 21788157 共 10 張皆為辦公區（地毯磨損、有接待櫃台），沒有拍廁所；同棟 5F 廁所老舊，4F 很可能相同，需現勘。 | Z12: 屋齡約43年 | AA12: 未提供 | AB12: 傑森愛華 2026/9/23清單第2頁；591 21788157（松華 李鴻鈞）、21429025、21908353 | AC12: 傑森愛華 張先生 0931-330823；松華 李鴻鈞 0939-060-379 | AD12: 591 物件頁 | AE12: 門牌定位：同旭寶大樓座標（25.0464096, 121.5494252） | AF12: 開啟地圖
A13: 待確認實坪 | B13: 12 | C13: J18 | D13: 忠孝東路四段×延吉街 4F | E13: 大安 | F13: 忠孝東路4段VS延吉街 | G13: 4F | H13: 276 | J13: 清單只有坪數276（未說明權狀或實坪） | K13: 504000 | L13: 480,000 未稅（@1,739）→ 含稅 504,000（傑森愛華 9/22 與 9/23 兩份清單同價） | N13: =IF(K13="","",K13+N(M13)) -> 504000 | O13: =IF(OR(I13="",N13=""),"",N13/I13) | P13: =IF(I13="","未揭露",IF(I13>=0_條件與假設!$B$5,"✓","✗")) -> 未揭露 | Q13: =IF(K13="","未提供",IF(K13<=0_條件與假設!$B$6,"≤45萬",IF(K13<=0_條件與假設!$B$7,"45～55萬","超過55萬"))) -> 45～55萬 | R13: 國父紀念館 | S13: 藍 | T13: 300 | U13: 5 | V13: =IF(U13="","未確認",IF(U13<=0_條件與假設!$B$8,"✓",IF(U13<=16,"△ 11～16分","✗"))) -> ✓ | W13: 待確認：實坪未揭露（權狀276坪）；已符合：月租50.4萬（45～55萬） · 國父紀念館(藍) 5分 | X13: 實坪未揭露；門牌與大樓名稱為推定；管理費未提供；廁所需現勘 | Y13: 廁所無照片：傑森愛華清單 3 張（外觀、毛胚室內、窗景），沒有拍廁所。需現勘。 | Z13: 推定大樓1982/08竣工（好房網） | AA13: 未提供 | AB13: 傑森愛華 9/22清單（J18）、9/23清單第1頁 | AC13: 傑森愛華 張先生 0931-330823 | AD13: 傑森愛華清單 第1頁 | AE13: 概略位置：忠孝東路四段×延吉街口（清單未給門牌）（25.0413459, 121.5545064） | AF13: 開啟地圖
A14: 待確認實坪 | B14: 13 | C14: N07 | D14: 忠孝東路一段 11F（台北車站） | E14: 中正 | F14: 忠孝東路一段 | G14: 11F/12F | H14: 266.78 | J14: 591 原文「權狀約266.78坪、低公設比」 | K14: 533500 | L14: 533,500 含稅（591 19506910） | N14: =IF(K14="","",K14+N(M14)) -> 533500 | O14: =IF(OR(I14="",N14=""),"",N14/I14) | P14: =IF(I14="","未揭露",IF(I14>=0_條件與假設!$B$5,"✓","✗")) -> 未揭露 | Q14: =IF(K14="","未提供",IF(K14<=0_條件與假設!$B$6,"≤45萬",IF(K14<=0_條件與假設!$B$7,"45～55萬","超過55萬"))) -> 45～55萬 | R14: 台北車站 | S14: 紅藍 | T14: 171 | U14: 3 | V14: =IF(U14="","未確認",IF(U14<=0_條件與假設!$B$8,"✓",IF(U14<=16,"△ 11～16分","✗"))) -> ✓ | W14: 待確認：實坪未揭露（權狀266.78坪）；已符合：月租53.4萬（45～55萬） · 台北車站(紅藍) 3分 | X14: 591 刊登已下架（9/24 查），需確認是否仍可租；實坪未揭露；管理費未提供；廁所需現勘 | Y14: 廁所無照片：591 19506910 共 10 張皆為空辦公區（部分天花板板材缺、地面有污漬），沒有拍廁所。需現勘。 | Z14: 未提供 | AA14: 未提供 | AB14: 591 19506910（尚揚 陳先生） | AC14: 尚揚 陳先生 0906-118-677 | AD14: 591 物件頁 | AE14: 無法定位：沒有門牌也沒有座標 | AF14: —
A15: 待確認實坪 | B15: 14 | C15: N14 | D15: 中山北路三段 6F（民權西路站） | E15: 中山 | F15: 中山北路三段 | G15: 6F/14F | H15: 265.93 | J15: 591 只寫「使用坪數265.93」，無分項 | K15: 385599 | L15: 385,599（591 22010409，含車位、含管理費，稅別未寫） | M15: 0 | N15: =IF(K15="","",K15+N(M15)) -> 385599 | O15: =IF(OR(I15="",N15=""),"",N15/I15) | P15: =IF(I15="","未揭露",IF(I15>=0_條件與假設!$B$5,"✓","✗")) -> 未揭露 | Q15: =IF(K15="","未提供",IF(K15<=0_條件與假設!$B$6,"≤45萬",IF(K15<=0_條件與假設!$B$7,"45～55萬","超過55萬"))) -> ≤45萬 | R15: 民權西路 | S15: 紅 | T15: 170 | U15: 3 | V15: =IF(U15="","未確認",IF(U15<=0_條件與假設!$B$8,"✓",IF(U15<=16,"△ 11～16分","✗"))) -> ✓ | W15: 待確認：實坪未揭露（權狀265.93坪）；已符合：月租38.6萬 · 民權西路(紅) 3分 | X15: 實坪未揭露；稅別未寫；大樓名稱未揭露；廁所需現勘 | Y15: 廁所無照片：591 只有 1 張照片（捷運站），室內與廁所都沒有拍。需現勘。 | Z15: 未提供 | AA15: 含車位 | AB15: 591 22010409（兆淇 鄭先生） | AC15: 兆淇 鄭先生 0960-539-161 | AD15: 591 物件頁 | AE15: 概略位置：591 22010409 物件頁地圖座標（門牌未揭露，591 標點可能為概略位置）（25.063996, 121.5208493） | AF15: 開啟地圖
A16: 待確認實坪 | B16: 15 | C16: N06 | D16: 忠孝東路一段 2F（善導寺站） | E16: 中正 | F16: 忠孝東路一段 | G16: 2F/21F | H16: 261.4 | J16: 591 原文「權狀約261.4坪（室內實際使用坪數以現場丈量或地政謄本為準）」 | K16: 421872 | L16: 421,872（591 20214332 等7筆同價，稅別未寫）；另有 480,000（住商南門 21553405／21867832） | N16: =IF(K16="","",K16+N(M16)) -> 421872 | O16: =IF(OR(I16="",N16=""),"",N16/I16) | P16: =IF(I16="","未揭露",IF(I16>=0_條件與假設!$B$5,"✓","✗")) -> 未揭露 | Q16: =IF(K16="","未提供",IF(K16<=0_條件與假設!$B$6,"≤45萬",IF(K16<=0_條件與假設!$B$7,"45～55萬","超過55萬"))) -> ≤45萬 | R16: 善導寺 | S16: 藍 | T16: 119 | U16: 2 | V16: =IF(U16="","未確認",IF(U16<=0_條件與假設!$B$8,"✓",IF(U16<=16,"△ 11～16分","✗"))) -> ✓ | W16: 待確認：實坪未揭露（權狀261.4坪）；已符合：月租42.2萬 · 善導寺(藍) 2分 | X16: 實坪未揭露；租金稅別未寫；兩種報價（42.2萬／48萬）；廁所需現勘 | Y16: 廁所無照片：591 20214332 共 14 張：辦公區、吧檯茶水區、戶外露台，沒有拍廁所。需現勘。 | Z16: 未提供 | AA16: 平面式 | AB16: 591 20214332（尚揚 陳先生）、21980734、21234693、21588975、21788512、22020729、22019214、21939596；21553405、21804380、21867832 | AC16: 尚揚 陳先生 0906-118-677 | AD16: 591 物件頁 | AE16: 概略位置：591 20214332 物件頁地圖座標（門牌未揭露，591 標點可能為概略位置）（25.0452963, 121.5244289） | AF16: 開啟地圖
A17: 待確認實坪 | B17: 16 | C17: N15 | D17: 民生東路二段 6F（仲介稱使用約226坪） | E17: 中山 | F17: 民生東路二段 | G17: 6F/12F | H17: 255.18 | J17: 591 21985150 標題「使用約226坪」（仲介口述，無謄本分項）；21595066 寫255.18坪 | K17: 507565 | L17: 483,395 未含稅（591 21595066）→ 含稅 507,565 | N17: =IF(K17="","",K17+N(M17)) -> 507565 | O17: =IF(OR(I17="",N17=""),"",N17/I17) | P17: =IF(I17="","未揭露",IF(I17>=0_條件與假設!$B$5,"✓","✗")) -> 未揭露 | Q17: =IF(K17="","未提供",IF(K17<=0_條件與假設!$B$6,"≤45萬",IF(K17<=0_條件與假設!$B$7,"45～55萬","超過55萬"))) -> 45～55萬 | R17: 行天宮(橘) 188m | V17: =IF(U17="","未確認",IF(U17<=0_條件與假設!$B$8,"✓",IF(U17<=16,"△ 11～16分","✗"))) -> 未確認 | W17: 待確認：實坪未揭露（權狀255.18坪） · 綠紅藍捷運距離未確認（最近 行天宮(橘) 188m）；已符合：月租50.8萬（45～55萬） | X17: 實坪只有仲介口述；綠紅藍捷運距離未確認（概略座標推算松江南京約780m）；稅別依據（591 21595066「未含稅」）已下架，現存刊登未寫稅別 | Y17: 廁所新：廁所為新裝修（591 21985150 照片 8、9：深色石材牆面、檯面式洗手台、新式小便斗）；辦公區天花有部分線材外露待整理；同戶 591 21812612 內文寫「廁所設於室內」。 | Z17: 未提供 | AA17: 平面式 | AB17: 591 21985150（弘浥 張先生）、21595066（兆淇 童先生）、21812612、21635522；591 21812612（易信 王先生 0955-866-400，255坪權狀、483,395、3年） | AC17: 弘浥 張先生 0920-323-930；易信國際 王先生 0955-866-400 | AD17: 591 物件頁 | AE17: 概略位置：591 21985150 物件頁地圖座標（門牌未揭露，591 標點可能為概略位置）（25.0588777, 121.531561） | AF17: 開啟地圖
A18: 待確認實坪 | B18: 17 | C18: S06 | D18: 八德大樓 7F（出租254.06坪） | E18: 中山 | F18: 八德路二段 | G18: 7F/12F | H18: 254.06 | J18: 信義 CZ05587：整筆權狀786.72、主322.97＋附12.15（整筆，數字異常），出租部分實坪未寫 | K18: 381090 | L18: 381,090（信義刊登）；591 22053377 254坪 381,000 | M18: 41920 | N18: =IF(K18="","",K18+N(M18)) -> 423010 | O18: =IF(OR(I18="",N18=""),"",N18/I18) | P18: =IF(I18="","未揭露",IF(I18>=0_條件與假設!$B$5,"✓","✗")) -> 未揭露 | Q18: =IF(K18="","未提供",IF(K18<=0_條件與假設!$B$6,"≤45萬",IF(K18<=0_條件與假設!$B$7,"45～55萬","超過55萬"))) -> ≤45萬 | R18: 忠孝復興 | S18: 藍 | T18: 620 | U18: 11 | V18: =IF(U18="","未確認",IF(U18<=0_條件與假設!$B$8,"✓",IF(U18<=16,"△ 11～16分","✗"))) -> △ 11～16分 | W18: 待確認：實坪未揭露（權狀254.06坪） · 捷運忠孝復興(藍) 11分（>10分）；已符合：月租38.1萬 | X18: 出租部分實坪未揭露；稅別未寫 | Y18: 廁所新：與 S11 同棟同規格：廁所新裝修（信義 CZ05587 照片 H）、茶水間新（照片 G）。 | Z18: 屋齡30.1年 | AA18: 無 | AB18: 信義房屋 CZ05587；591 20991786、22053377、21808787、21595262 | AC18: 信義 林嘉君 0912-313-517 | AD18: 信義全球物件頁 | AE18: 物件頁座標：信義全球物件座標（25.046277, 121.540437） | AF18: 開啟地圖
A19: 待確認實坪 | B19: 18 | C19: N09 | D19: 長春路 8F（松江南京站） | E19: 中山 | F19: 長春路 | G19: 8F/12F | H19: 253 | J19: 591 只寫「使用坪數253坪」，無分項 | K19: 480035 | L19: 480,035（591 22061922，稅別未寫） | N19: =IF(K19="","",K19+N(M19)) -> 480035 | O19: =IF(OR(I19="",N19=""),"",N19/I19) | P19: =IF(I19="","未揭露",IF(I19>=0_條件與假設!$B$5,"✓","✗")) -> 未揭露 | Q19: =IF(K19="","未提供",IF(K19<=0_條件與假設!$B$6,"≤45萬",IF(K19<=0_條件與假設!$B$7,"45～55萬","超過55萬"))) -> 45～55萬 | R19: 松江南京 | S19: 綠 | T19: 310 | U19: 6 | V19: =IF(U19="","未確認",IF(U19<=0_條件與假設!$B$8,"✓",IF(U19<=16,"△ 11～16分","✗"))) -> ✓ | W19: 待確認：實坪未揭露（權狀253坪）；已符合：月租48.0萬（45～55萬） · 松江南京(綠) 6分 | X19: 實坪未揭露；租金稅別未寫；管理費未提供；廁所需現勘 | Y19: 廁所無照片：591 共 4 張皆為辦公區（開放式天花、地毯），沒有拍廁所。需現勘。 | Z19: 未提供 | AA19: 未提供 | AB19: 591 22061922（易信 王先生） | AC19: 易信國際 王先生 0955-866-400 | AD19: 591 物件頁 | AE19: 概略位置：591 22061922 物件頁地圖座標（門牌未揭露，591 標點可能為概略位置）（25.0545594, 121.5342379） | AF19: 開啟地圖
A20: 待確認實坪 | B20: 19 | C20: N27 | D20: 南京東路五段 3F（南京三民站） | E20: 松山 | F20: 南京東路五段 | G20: 3F/16F | H20: 243 | J20: 591 原文「廣告坪數為權狀坪數」；公設比需≤9.5%才可能達220 | K20: 534754 | L20: 534,754（591 22061968，稅別未寫；若為未稅，含稅561,492將超過上限） | N20: =IF(K20="","",K20+N(M20)) -> 534754 | O20: =IF(OR(I20="",N20=""),"",N20/I20) | P20: =IF(I20="","未揭露",IF(I20>=0_條件與假設!$B$5,"✓","✗")) -> 未揭露 | Q20: =IF(K20="","未提供",IF(K20<=0_條件與假設!$B$6,"≤45萬",IF(K20<=0_條件與假設!$B$7,"45～55萬","超過55萬"))) -> 45～55萬 | R20: 南京三民 | S20: 綠 | T20: 48 | U20: 1 | V20: =IF(U20="","未確認",IF(U20<=0_條件與假設!$B$8,"✓",IF(U20<=16,"△ 11～16分","✗"))) -> ✓ | W20: 待確認：實坪未揭露（權狀243坪）；已符合：月租53.5萬（45～55萬） · 南京三民(綠) 1分 | X20: 實坪未揭露；稅別未寫（未稅則超過55萬）；廁所需現勘 | Y20: 廁所無照片：591 共 4 張（辦公區、外觀），沒有拍廁所。需現勘。 | Z20: 未提供 | AA20: 未提供 | AB20: 591 22061968（易信 王先生） | AC20: 易信國際 王先生 0955-866-400 | AD20: 591 物件頁 | AE20: 概略位置：591 22061968 物件頁地圖座標（門牌未揭露，591 標點可能為概略位置）（25.0510453, 121.5640687） | AF20: 開啟地圖
A21: 不符合 | B21: 20 | C21: N19 | D21: 信義大樓 5F | E21: 信義 | F21: 松仁路 | G21: 5F/23F | H21: 330.42 | I21: 300.54 | J21: 信義 C905082：主264.78＋附35.76 | K21: 561714 | L21: 561,714（信義刊登） | M21: 49563 | N21: =IF(K21="","",K21+N(M21)) -> 611277 | O21: =IF(OR(I21="",N21=""),"",N21/I21) -> 2033.9289 | P21: =IF(I21="","未揭露",IF(I21>=0_條件與假設!$B$5,"✓","✗")) -> ✓ | Q21: =IF(K21="","未提供",IF(K21<=0_條件與假設!$B$6,"≤45萬",IF(K21<=0_條件與假設!$B$7,"45～55萬","超過55萬"))) -> 超過55萬 | R21: 象山 | S21: 紅 | T21: 950 | U21: 16 | V21: =IF(U21="","未確認",IF(U21<=0_條件與假設!$B$8,"✓",IF(U21<=16,"△ 11～16分","✗"))) -> △ 11～16分 | W21: 不符：月租561,714超過55萬 | X21: 稅別未寫 | Y21: 同棟廁所新：同棟 10F、21F 廁所為新裝修；本層未另拍。 | Z21: 屋齡29.2年 | AA21: 無 | AB21: 信義房屋 C905082 | AC21: 信義 許雅傑 0966-513-725 | AD21: 信義全球物件頁 | AE21: 物件頁座標：同信義大樓座標（25.024307, 121.569847） | AF21: 開啟地圖
A22: 不符合 | B22: 21 | C22: N20 | D22: 信義大樓 9F | E22: 信義 | F22: 松仁路 | G22: 9F/23F | H22: 330.22 | I22: 300.44 | J22: 信義 C904199：主249.55＋附50.89 | K22: 577885 | L22: 577,885（信義刊登） | M22: 49533 | N22: =IF(K22="","",K22+N(M22)) -> 627418 | O22: =IF(OR(I22="",N22=""),"",N22/I22) -> 2088.3304 | P22: =IF(I22="","未揭露",IF(I22>=0_條件與假設!$B$5,"✓","✗")) -> ✓ | Q22: =IF(K22="","未提供",IF(K22<=0_條件與假設!$B$6,"≤45萬",IF(K22<=0_條件與假設!$B$7,"45～55萬","超過55萬"))) -> 超過55萬 | R22: 象山 | S22: 紅 | T22: 950 | U22: 16 | V22: =IF(U22="","未確認",IF(U22<=0_條件與假設!$B$8,"✓",IF(U22<=16,"△ 11～16分","✗"))) -> △ 11～16分 | W22: 不符：月租577,885超過55萬 | X22: 稅別未寫 | Y22: 同棟廁所新：同棟 10F、21F 廁所為新裝修；本層未另拍。 | Z22: 屋齡28.2年 | AA22: 無 | AB22: 信義房屋 C904199 | AC22: 信義 許雅傑 0966-513-725 | AD22: 信義全球物件頁 | AE22: 物件頁座標：同信義大樓座標（25.024307, 121.569847） | AF22: 開啟地圖
A23: 不符合 | B23: 22 | C23: S14 | D23: 復興南路稀有大空間地下室 B1 | E23: 大安 | F23: 復興南路一段 | G23: B1/7F | H23: 277.81 | I23: 256.87 | J23: 上一版資料：實用坪256.87 | K23: 300000 | L23: 300,000（含稅） | N23: =IF(K23="","",K23+N(M23)) -> 300000 | O23: =IF(OR(I23="",N23=""),"",N23/I23) -> 1167.9059 | P23: =IF(I23="","未揭露",IF(I23>=0_條件與假設!$B$5,"✓","✗")) -> ✓ | Q23: =IF(K23="","未提供",IF(K23<=0_條件與假設!$B$6,"≤45萬",IF(K23<=0_條件與假設!$B$7,"45～55萬","超過55萬"))) -> ≤45萬 | R23: 忠孝復興 | S23: 藍 | T23: 290 | U23: 5 | V23: =IF(U23="","未確認",IF(U23<=0_條件與假設!$B$8,"✓",IF(U23<=16,"△ 11～16分","✗"))) -> ✓ | W23: 不符：地下室／1樓 | Y23: 未檢視：本案不符合條件，本輪未逐張檢視廁所照片；如需要可補看。 | Z23: 46年 | AA23: 無 | AB23: 信義房屋 | AC23: 信義房屋 和平店 傅椿淵 0988-100-122 | AD23: 信義 本戶·5張照片（C348029） | AE23: 物件頁座標：信義全球物件座標（25.0436965, 121.5455521） | AF23: 開啟地圖
A24: 不符合 | B24: 23 | C24: N18 | D24: 新設工大樓 6C（中山北路三段） | E24: 中山 | F24: 中山北路三段22號之1 | G24: 6F/14F | H24: 353.16 | I24: 234.22 | J24: 591 原文「權狀面積353.16坪，淨面積234.22坪」 | K24: 574768 | L24: 547,398 未稅（1,550/坪）→ 含稅 574,768 | M24: 35316 | N24: =IF(K24="","",K24+N(M24)) -> 610084 | O24: =IF(OR(I24="",N24=""),"",N24/I24) -> 2604.7477 | P24: =IF(I24="","未揭露",IF(I24>=0_條件與假設!$B$5,"✓","✗")) -> ✓ | Q24: =IF(K24="","未提供",IF(K24<=0_條件與假設!$B$6,"≤45萬",IF(K24<=0_條件與假設!$B$7,"45～55萬","超過55萬"))) -> 超過55萬 | R24: 民權西路 | S24: 紅 | T24: 66 | U24: 2 | V24: =IF(U24="","未確認",IF(U24<=0_條件與假設!$B$8,"✓",IF(U24<=16,"△ 11～16分","✗"))) -> ✓ | W24: 不符：月租574,768超過55萬 | Y24: 未檢視：本案不符合條件，本輪未逐張檢視廁所照片；如需要可補看。 | Z24: 未提供 | AA24: 不含 | AB24: 591 21672889（大同開發 林副理） | AC24: 大同開發 林副理 02-25925252#2781／0911-033-078 | AD24: 591 物件頁 | AE24: 無座標；依門牌搜尋 | AF24: 開啟地圖
A25: 不符合 | B25: 24 | C25: N21 | D25: 信義大樓 22F | E25: 信義 | F25: 松仁路 | G25: 22F/23F | H25: 243.03 | I25: 221.05 | J25: 信義 C904442：主152.65＋附68.40 | K25: 595424 | L25: 595,424（信義刊登） | M25: 36455 | N25: =IF(K25="","",K25+N(M25)) -> 631879 | O25: =IF(OR(I25="",N25=""),"",N25/I25) -> 2858.5343 | P25: =IF(I25="","未揭露",IF(I25>=0_條件與假設!$B$5,"✓","✗")) -> ✓ | Q25: =IF(K25="","未提供",IF(K25<=0_條件與假設!$B$6,"≤45萬",IF(K25<=0_條件與假設!$B$7,"45～55萬","超過55萬"))) -> 超過55萬 | R25: 象山 | S25: 紅 | T25: 950 | U25: 16 | V25: =IF(U25="","未確認",IF(U25<=0_條件與假設!$B$8,"✓",IF(U25<=16,"△ 11～16分","✗"))) -> △ 11～16分 | W25: 不符：月租595,424超過55萬 | X25: 稅別未寫 | Y25: 同棟廁所新：同棟 10F、21F 廁所為新裝修；本層未另拍。 | Z25: 屋齡28.2年 | AA25: 無 | AB25: 信義房屋 C904442 | AC25: 信義 許雅傑 0966-513-725 | AD25: 信義全球物件頁 | AE25: 物件頁座標：同信義大樓座標（25.024307, 121.569847） | AF25: 開啟地圖
A26: 不符合 | B26: 25 | C26: S04 | D26: 光復南路大坪數辦公 6F | E26: 松山 | F26: 光復南路 | G26: 6F/11F | H26: 211.38 | I26: 211.38 | J26: 尚揚物調表：主建物＋附屬211.38（分割戶） | K26: 401622 | L26: 401,622 含稅（尚揚物調表）；信義 388,500 | M26: 18000 | N26: =IF(K26="","",K26+N(M26)) -> 419622 | O26: =IF(OR(I26="",N26=""),"",N26/I26) -> 1985.1547 | P26: =IF(I26="","未揭露",IF(I26>=0_條件與假設!$B$5,"✓","✗")) -> ✗ | Q26: =IF(K26="","未提供",IF(K26<=0_條件與假設!$B$6,"≤45萬",IF(K26<=0_條件與假設!$B$7,"45～55萬","超過55萬"))) -> ≤45萬 | R26: 國父紀念館 | S26: 藍 | T26: 580 | U26: 10 | V26: =IF(U26="","未確認",IF(U26<=0_條件與假設!$B$8,"✓",IF(U26<=16,"△ 11～16分","✗"))) -> ✓ | W26: 不符：實坪211.38（差8.6坪） | Y26: 廁所無照片：尚揚照片為毛胚（天花未封、水泥地），沒有拍廁所。 | Z26: 51年 | AA26: 可另租(年租2.4萬≈2,000/月) | AB26: 尚揚物調表（光復大樓6F分割，光復南路35號）；信義 C328671 | AC26: 信義房屋 松江南京店 汪智凱 0921-427-889 | AD26: 信義 本戶·19張照片（C328671） | AE26: 物件頁座標：信義全球物件座標（25.0465695, 121.5579704） | AF26: 開啟地圖
A27: 不符合 | B27: 26 | C27: D | D27: 敦化財經大樓 4F之1 | E27: 松山 | F27: 敦化北路214號 | G27: 4F/11F(B2) | H27: 220.07 | I27: 207.21 | J27: 尚揚物調表：主建物207.21 | K27: 440140 | L27: 440,140 含稅（尚揚物調表）；591 同戶 386,839 稅別未寫 | M27: 48415 | N27: =IF(K27="","",K27+N(M27)) -> 488555 | O27: =IF(OR(I27="",N27=""),"",N27/I27) -> 2357.7771 | P27: =IF(I27="","未揭露",IF(I27>=0_條件與假設!$B$5,"✓","✗")) -> ✗ | Q27: =IF(K27="","未提供",IF(K27<=0_條件與假設!$B$6,"≤45萬",IF(K27<=0_條件與假設!$B$7,"45～55萬","超過55萬"))) -> ≤45萬 | R27: 中山國中(棕) 404m（591寫明） | V27: =IF(U27="","未確認",IF(U27<=0_條件與假設!$B$8,"✓",IF(U27<=16,"△ 11～16分","✗"))) -> 未確認 | W27: 不符：實坪207.21（差12.8坪） | X27: 591 與物調表租金／管理費不同（446,480 vs 440,140；47,840 vs 48,415） | Y27: 廁所在外：物調表註明「廁所在外」（公共廁所，非本戶專用）；尚揚照片大多為毛胚（天花拆除、管線外露），沒有拍廁所；591 21711753 共 11 張為大樓外觀、大廳（石材）與周邊，也沒有室內與廁所照片。 | Z27: 35年* | AA27: 坡平另租8,000 | AB27: 尚揚物調表（張正修）；591 20880830、20380770、21711753、21643233（標題「使用約207坪」） | AC27: 尚揚國際 張正修 0937-519-365 | AD27: 591 疑同戶4F 220坪·星辰地產 | AE27: 概略位置：591 21711753 物件頁地圖座標（門牌未揭露，591 標點可能為概略位置）（25.0587943, 121.5464862） | AF27: 開啟地圖
A28: 不符合 | B28: 27 | C28: S15 | D28: 永春地下大空間店商辦 B1 | E28: 信義 | F28: 松德路 | G28: B1/12F | H28: 213.56 | I28: 204.08 | J28: 上一版資料：實用坪204.08 | K28: 218000 | L28: 218,000（含稅） | M28: 18980 | N28: =IF(K28="","",K28+N(M28)) -> 236980 | O28: =IF(OR(I28="",N28=""),"",N28/I28) -> 1161.2113 | P28: =IF(I28="","未揭露",IF(I28>=0_條件與假設!$B$5,"✓","✗")) -> ✗ | Q28: =IF(K28="","未提供",IF(K28<=0_條件與假設!$B$6,"≤45萬",IF(K28<=0_條件與假設!$B$7,"45～55萬","超過55萬"))) -> ≤45萬 | R28: 永春 | S28: 藍 | T28: 190 | U28: 4 | V28: =IF(U28="","未確認",IF(U28<=0_條件與假設!$B$8,"✓",IF(U28<=16,"△ 11～16分","✗"))) -> ✓ | W28: 不符：地下室／1樓；實坪204.08（差15.9坪） | Y28: 未檢視：本案不符合條件，本輪未逐張檢視廁所照片；如需要可補看。 | Z28: 36年 | AA28: 2個升降機械 | AB28: 信義房屋 | AC28: 信義房屋 忠孝永春店 張超鈞 0905-809-808 | AD28: 信義 本戶·18張照片（C360351） | AE28: 物件頁座標：信義全球物件座標（25.039575, 121.57748） | AF28: 開啟地圖
A29: 不符合 | B29: 28 | C29: E | D29: 國泰世華銀行大樓 6F | E29: 大安 | F29: 仁愛路四段85號 | G29: 6F/14F(B2) | H29: 265.72 | I29: 203.79 | J29: 上一版資料：實用坪203.79 | K29: 502211 | L29: 502,211（含稅） | N29: =IF(K29="","",K29+N(M29)) -> 502211 | O29: =IF(OR(I29="",N29=""),"",N29/I29) -> 2464.3555 | P29: =IF(I29="","未揭露",IF(I29>=0_條件與假設!$B$5,"✓","✗")) -> ✗ | Q29: =IF(K29="","未提供",IF(K29<=0_條件與假設!$B$6,"≤45萬",IF(K29<=0_條件與假設!$B$7,"45～55萬","超過55萬"))) -> 45～55萬 | R29: 忠孝敦化 | S29: 藍 | T29: 440 | U29: 8 | V29: =IF(U29="","未確認",IF(U29<=0_條件與假設!$B$8,"✓",IF(U29<=16,"△ 11～16分","✗"))) -> ✓ | W29: 不符：實坪203.79（差16.2坪） | Y29: 未檢視：本案不符合條件，本輪未逐張檢視廁所照片；如需要可補看。 | Z29: 43年 | AA29: 租金內含2坡平+2機車位 | AB29: 物調表 | AC29: 尚揚國際 葉建成 0973-894168 | AD29: 591 物件頁（同戶） | AE29: 門牌定位：Google地圖：仁愛路四段85號（25.0382915, 121.5477716） | AF29: 開啟地圖
A30: 不符合 | B30: 29 | C30: S03 | D30: 敦北長城大樓 3F | E30: 松山 | F30: 八德路三段(長城大樓) | G30: 3F/16F | H30: 225.83 | I30: 201.29 | J30: 尚揚物調表／信義 CZ05326：主189.31＋附11.98 | K30: 474500 | L30: 信義 474,500；尚揚物調表 513,892 含稅（個人稅別） | M30: 27100 | N30: =IF(K30="","",K30+N(M30)) -> 501600 | O30: =IF(OR(I30="",N30=""),"",N30/I30) -> 2491.9271 | P30: =IF(I30="","未揭露",IF(I30>=0_條件與假設!$B$5,"✓","✗")) -> ✗ | Q30: =IF(K30="","未提供",IF(K30<=0_條件與假設!$B$6,"≤45萬",IF(K30<=0_條件與假設!$B$7,"45～55萬","超過55萬"))) -> 45～55萬 | R30: 台北小巨蛋 | S30: 綠 | T30: 400 | U30: 7 | V30: =IF(U30="","未確認",IF(U30<=0_條件與假設!$B$8,"✓",IF(U30<=16,"△ 11～16分","✗"))) -> ✓ | W30: 不符：實坪201.29（差18.7坪） | Y30: 廁所無照片：尚揚照片為現況裝潢（會議室、輕鋼架天花），沒有拍廁所；信義頁面寫「男女分廁」。 | Z30: 34年 | AA30: 無 | AB30: 信義房屋 | AC30: 信義房屋 商仲一部 陳霆瑋 0938-893-639 | AD30: 信義 本戶·21張照片（CZ05326） | AE30: 物件頁座標：信義全球物件座標（25.048055, 121.551782） | AF30: 開啟地圖
A31: 不符合 | B31: 30 | C31: N17 | D31: 松哖大樓 2F | E31: 中山 | F31: 民生東路二段161號＋163號2樓 | G31: 2F/12F(B1) | H31: 227.15 | I31: 198.26 | J31: 尚揚物調表：主建物＋附屬198.26 | K31: 500000 | L31: 500,000 含稅（尚揚物調表）；591 同樓層 439,450～500,000 多筆 | M31: 40000 | N31: =IF(K31="","",K31+N(M31)) -> 540000 | O31: =IF(OR(I31="",N31=""),"",N31/I31) -> 2723.6962 | P31: =IF(I31="","未揭露",IF(I31>=0_條件與假設!$B$5,"✓","✗")) -> ✗ | Q31: =IF(K31="","未提供",IF(K31<=0_條件與假設!$B$6,"≤45萬",IF(K31<=0_條件與假設!$B$7,"45～55萬","超過55萬"))) -> 45～55萬 | R31: 行天宮(橘) 約185～299m | V31: =IF(U31="","未確認",IF(U31<=0_條件與假設!$B$8,"✓",IF(U31<=16,"△ 11～16分","✗"))) -> 未確認 | W31: 不符：實坪198.26（差21.7坪） | Y31: 廁所無照片：尚揚照片為辦公區（水泥地坪、部分天花拆），沒有拍廁所；591 20941554 共 10 張也都是空室（天花部分拆除），沒有廁所。 | Z31: 使照77/03/07（屋齡約38年） | AA31: 坡平另租7,000～8,000 | AB31: 尚揚物調表（劉品汯）；591 21593366、21555597、21985155（標題「使用約180坪」）、22044758、20941554、20864693 | AC31: 尚揚 劉品汯 0901-407-026 | AD31: 591 物件頁 | AE31: 概略位置：591 20941554 物件頁地圖座標（門牌未揭露，591 標點可能為概略位置）（25.0572705, 121.5327198） | AF31: 開啟地圖
A32: 不符合 | B32: 31 | C32: N26 | D32: 安和路一段 11F | E32: 大安 | F32: 安和路一段 | G32: 11F/18F | H32: 224.31 | I32: 192.04 | J32: 住商 WR81767：主173.05＋附18.99 | K32: 486000 | L32: 48.6萬（住商） | M32: 30860 | N32: =IF(K32="","",K32+N(M32)) -> 516860 | O32: =IF(OR(I32="",N32=""),"",N32/I32) -> 2691.4185 | P32: =IF(I32="","未揭露",IF(I32>=0_條件與假設!$B$5,"✓","✗")) -> ✗ | Q32: =IF(K32="","未提供",IF(K32<=0_條件與假設!$B$6,"≤45萬",IF(K32<=0_條件與假設!$B$7,"45～55萬","超過55萬"))) -> 45～55萬 | R32: 忠孝敦化 | S32: 藍 | T32: 255 | U32: 5 | V32: =IF(U32="","未確認",IF(U32<=0_條件與假設!$B$8,"✓",IF(U32<=16,"△ 11～16分","✗"))) -> ✓ | W32: 不符：實坪192.04（差28.0坪） | X32: 稅別未寫 | Y32: 未檢視：本案不符合條件，本輪未逐張檢視廁所照片；如需要可補看。 | Z32: 屋齡38.5年 | AA32: 可租，坡道平面 | AB32: 住商不動產 WR81767 | AC32: 住商仁愛光復 關文乾 02-27764000 | AD32: 住商物件頁 | AE32: 無法定位：沒有門牌也沒有座標 | AF32: —
A33: 不符合 | B33: 32 | C33: F | D33: 友聯大樓 5F | E33: 松山 | F33: 南京東路五段89號 | G33: 5F/15F(B3) | H33: 203.26 | I33: 189.91 | J33: 上一版資料：實用坪189.91 | K33: 405504 | L33: 405,504（含稅） | N33: =IF(K33="","",K33+N(M33)) -> 405504 | O33: =IF(OR(I33="",N33=""),"",N33/I33) -> 2135.243 | P33: =IF(I33="","未揭露",IF(I33>=0_條件與假設!$B$5,"✓","✗")) -> ✗ | Q33: =IF(K33="","未提供",IF(K33<=0_條件與假設!$B$6,"≤45萬",IF(K33<=0_條件與假設!$B$7,"45～55萬","超過55萬"))) -> ≤45萬 | R33: 南京三民 | S33: 綠 | T33: 380 | U33: 7 | V33: =IF(U33="","未確認",IF(U33<=0_條件與假設!$B$8,"✓",IF(U33<=16,"△ 11～16分","✗"))) -> ✓ | W33: 不符：實坪189.91（差30.1坪） | Y33: 未檢視：本案不符合條件，本輪未逐張檢視廁所照片；如需要可補看。 | Z33: 36年 | AA33: 坡平另租7,000~8,000 | AB33: 物調表 | AC33: 尚揚國際 劉品汯 0901-407-026 | AD33: 大樓頁（好房網） | AE33: 門牌定位：Google地圖：南京東路五段89號（25.0517198, 121.5601141） | AF33: 開啟地圖
A34: 不符合 | B34: 33 | C34: A | D34: 安敦國際大樓 7F | E34: 大安 | F34: 安和路一段29號 | G34: 7F/18F(B4) | H34: 220.81 | I34: 189.32 | J34: 上一版資料：實用坪189.32 | K34: 420000 | L34: 420,000（含稅） | M34: 30913 | N34: =IF(K34="","",K34+N(M34)) -> 450913 | O34: =IF(OR(I34="",N34=""),"",N34/I34) -> 2381.7505 | P34: =IF(I34="","未揭露",IF(I34>=0_條件與假設!$B$5,"✓","✗")) -> ✗ | Q34: =IF(K34="","未提供",IF(K34<=0_條件與假設!$B$6,"≤45萬",IF(K34<=0_條件與假設!$B$7,"45～55萬","超過55萬"))) -> ≤45萬 | R34: 忠孝敦化 | S34: 藍 | T34: 185 | U34: 4 | V34: =IF(U34="","未確認",IF(U34<=0_條件與假設!$B$8,"✓",IF(U34<=16,"△ 11～16分","✗"))) -> ✓ | W34: 不符：實坪189.32（差30.7坪） | Y34: 未檢視：本案不符合條件，本輪未逐張檢視廁所照片；如需要可補看。 | Z34: 38年 | AA34: 租金內含2個坡平車位 | AB34: 物調表 | AC34: 尚揚國際 劉品汯 0901-407-026 | AD34: 591 本戶7F·14張照片 | AE34: 無座標；依門牌搜尋 | AF34: 開啟地圖
A35: 不符合 | B35: 34 | C35: B | D35: 中鼎大樓 15F之1 | E35: 大安 | F35: 敦化南路二段77號 | G35: 15F/22F(B2) | H35: 232.22 | I35: 183.22 | J35: 上一版資料：實用坪183.22 | K35: 451087 | L35: 451,087（含稅） | M35: 32511 | N35: =IF(K35="","",K35+N(M35)) -> 483598 | O35: =IF(OR(I35="",N35=""),"",N35/I35) -> 2639.4389 | P35: =IF(I35="","未揭露",IF(I35>=0_條件與假設!$B$5,"✓","✗")) -> ✗ | Q35: =IF(K35="","未提供",IF(K35<=0_條件與假設!$B$6,"≤45萬",IF(K35<=0_條件與假設!$B$7,"45～55萬","超過55萬"))) -> 45～55萬 | R35: 信義安和 | S35: 紅 | T35: 510 | U35: 9 | V35: =IF(U35="","未確認",IF(U35<=0_條件與假設!$B$8,"✓",IF(U35<=16,"△ 11～16分","✗"))) -> ✓ | W35: 不符：實坪183.22（差36.8坪） | Y35: 未檢視：本案不符合條件，本輪未逐張檢視廁所照片；如需要可補看。 | Z35: 42年 | AA35: 坡平另租10,000未稅 | AB35: 物調表 | AC35: 尚揚國際 王智平 0917-154-083 | AD35: 信義 本戶15F·15張照片（CZ05572） | AE35: 物件頁座標：信義全球物件座標(中鼎大樓)（25.030026, 121.549429） | AF35: 開啟地圖
A36: 不符合 | B36: 35 | C36: J15 | D36: 敦化南路2段(中鼎大樓 77號22樓) 22F 230坪 | E36: 大安 | F36: 敦化南路2段(中鼎大樓 77號22樓) | G36: 22F | H36: 230 | I36: 179 | J36: 上一版資料：實用坪179 | K36: 478170 | L36: 478,170（未稅×1.05） | M36: 36800 | N36: =IF(K36="","",K36+N(M36)) -> 514970 | O36: =IF(OR(I36="",N36=""),"",N36/I36) -> 2876.9274 | P36: =IF(I36="","未揭露",IF(I36>=0_條件與假設!$B$5,"✓","✗")) -> ✗ | Q36: =IF(K36="","未提供",IF(K36<=0_條件與假設!$B$6,"≤45萬",IF(K36<=0_條件與假設!$B$7,"45～55萬","超過55萬"))) -> 45～55萬 | R36: 信義安和 | S36: 紅 | T36: 510 | U36: 9 | V36: =IF(U36="","未確認",IF(U36<=0_條件與假設!$B$8,"✓",IF(U36<=16,"△ 11～16分","✗"))) -> ✓ | W36: 不符：實坪179（差41.0坪） | Y36: 未檢視：本案不符合條件，本輪未逐張檢視廁所照片；如需要可補看。 | Z36: 42年 | AA36: 1個12,000/月 | AB36: 傑森愛華 | AC36: 傑森愛華 張先生 0931-330823 | AD36: 傑森愛華單筆報表PDF（中鼎22F·3頁，含照片） | AE36: 物件頁座標：同中鼎大樓(信義全球座標)（25.030026, 121.549429） | AF36: 開啟地圖
A37: 不符合 | B37: 36 | C37: J12 | D37: 敦化南路2段 (中鼎大樓 77號2樓) 2F 222坪 | E37: 大安 | F37: 敦化南路2段 (中鼎大樓 77號2樓) | G37: 2F | H37: 222 | I37: 173 | J37: 上一版資料：實用坪173 | K37: 420000 | L37: 420,000（未稅×1.05） | M37: 33300 | N37: =IF(K37="","",K37+N(M37)) -> 453300 | O37: =IF(OR(I37="",N37=""),"",N37/I37) -> 2620.2312 | P37: =IF(I37="","未揭露",IF(I37>=0_條件與假設!$B$5,"✓","✗")) -> ✗ | Q37: =IF(K37="","未提供",IF(K37<=0_條件與假設!$B$6,"≤45萬",IF(K37<=0_條件與假設!$B$7,"45～55萬","超過55萬"))) -> ≤45萬 | R37: 信義安和 | S37: 紅 | T37: 510 | U37: 9 | V37: =IF(U37="","未確認",IF(U37<=0_條件與假設!$B$8,"✓",IF(U37<=16,"△ 11～16分","✗"))) -> ✓ | W37: 不符：實坪173（差47.0坪） | Y37: 未檢視：本案不符合條件，本輪未逐張檢視廁所照片；如需要可補看。 | Z37: 42年 | AA37: 2個各10,000/月 | AB37: 傑森愛華 | AC37: 傑森愛華 張先生 0931-330823 | AD37: 傑森愛華單筆報表PDF（中鼎2F·2頁，含照片） | AE37: 物件頁座標：同中鼎大樓(信義全球座標)（25.030026, 121.549429） | AF37: 開啟地圖
A38: 不符合 | B38: 37 | C38: S07 | D38: 明水路營業用商辦 4F | E38: 中山 | F38: 明水路(大直) | G38: 4F/10F | H38: 253.16 | I38: 166.77 | J38: 上一版資料：實用坪166.77 | K38: 350000 | L38: 350,000（含稅） | M38: 36676 | N38: =IF(K38="","",K38+N(M38)) -> 386676 | O38: =IF(OR(I38="",N38=""),"",N38/I38) -> 2318.6185 | P38: =IF(I38="","未揭露",IF(I38>=0_條件與假設!$B$5,"✓","✗")) -> ✗ | Q38: =IF(K38="","未提供",IF(K38<=0_條件與假設!$B$6,"≤45萬",IF(K38<=0_條件與假設!$B$7,"45～55萬","超過55萬"))) -> ≤45萬 | R38: 台北小巨蛋 | S38: 綠 | T38: 3310 | U38: 54 | V38: =IF(U38="","未確認",IF(U38<=0_條件與假設!$B$8,"✓",IF(U38<=16,"△ 11～16分","✗"))) -> ✗ | W38: 不符：實坪166.77（差53.2坪）；捷運台北小巨蛋(綠) 54分太遠；大直（依指示不列優先） | Y38: 未檢視：本案不符合條件，本輪未逐張檢視廁所照片；如需要可補看。 | Z38: 25年 | AA38: 5個坡道平面(含) | AB38: 信義房屋 | AC38: 信義房屋 商仲二部 陳泰利 0952-228-883 | AD38: 信義 本戶·12張照片（CZ03701） | AE38: 物件頁座標：信義全球物件座標（25.081444, 121.551799） | AF38: 開啟地圖
A39: 不符合 | B39: 38 | C39: Y2 | D39: 家美金融大樓 15F | E39: 信義 | F39: 忠孝東路五段(家美金融) | G39: 15F/28F | H39: 208.96 | I39: 164.05 | J39: 上一版資料：實用坪164.05 | K39: 398000 | L39: 398,000（含稅） | M39: 36435 | N39: =IF(K39="","",K39+N(M39)) -> 434435 | O39: =IF(OR(I39="",N39=""),"",N39/I39) -> 2648.1865 | P39: =IF(I39="","未揭露",IF(I39>=0_條件與假設!$B$5,"✓","✗")) -> ✗ | Q39: =IF(K39="","未提供",IF(K39<=0_條件與假設!$B$6,"≤45萬",IF(K39<=0_條件與假設!$B$7,"45～55萬","超過55萬"))) -> ≤45萬 | R39: 永春 | S39: 藍 | T39: 200 | U39: 4 | V39: =IF(U39="","未確認",IF(U39<=0_條件與假設!$B$8,"✓",IF(U39<=16,"△ 11～16分","✗"))) -> ✓ | W39: 不符：實坪164.05（差55.9坪） | Y39: 未檢視：本案不符合條件，本輪未逐張檢視廁所照片；如需要可補看。 | Z39: 33年 | AA39: 3個坡道+平面(信義頁;永慶未標) | AB39: 永慶房屋 | AC39: 永慶 南京光復直營店／信義 商仲二部 簡伊涵 0916-263-633／簡文章 0918-520-184 | AD39: 永慶 本戶15F·14張照片 | AE39: 物件頁座標：信義全球物件座標(家美金融)（25.040833, 121.578638） | AF39: 開啟地圖
A40: 不符合 | B40: 39 | C40: G | D40: 白宮企業大樓 5F | E40: 松山 | F40: 南京東路三段346號 | G40: 5F/12F(B1) | H40: 207.04 | I40: 156.93 | J40: 上一版資料：實用坪156.93 | K40: 360150 | L40: 360,150（含稅） | M40: 28984 | N40: =IF(K40="","",K40+N(M40)) -> 389134 | O40: =IF(OR(I40="",N40=""),"",N40/I40) -> 2479.6661 | P40: =IF(I40="","未揭露",IF(I40>=0_條件與假設!$B$5,"✓","✗")) -> ✗ | Q40: =IF(K40="","未提供",IF(K40<=0_條件與假設!$B$6,"≤45萬",IF(K40<=0_條件與假設!$B$7,"45～55萬","超過55萬"))) -> ≤45萬 | R40: 台北小巨蛋 | S40: 綠 | T40: 390 | U40: 7 | V40: =IF(U40="","未確認",IF(U40<=0_條件與假設!$B$8,"✓",IF(U40<=16,"△ 11～16分","✗"))) -> ✓ | W40: 不符：實坪156.93（差63.1坪） | Y40: 未檢視：本案不符合條件，本輪未逐張檢視廁所照片；如需要可補看。 | Z40: 48年 | AA40: 無車位 | AB40: 物調表 | AC40: 尚揚國際 張正修 0937-519-365 | AD40: 好房網大樓頁·10張照片（本戶207坪整層無公開頁） | AE40: 門牌定位：Google地圖：南京東路三段346號白宮企業大樓（25.0513632, 121.5480628） | AF40: 開啟地圖
...

Sheet B_優先案詳情
A1: 欄位 | B1: S05 | C1: N04 | D1: C | E1: N02 | F1: S12 | G1: N01 | H1: N05 | I1: N08 | J1: S11 | K1: N10 | L1: N11 | M1: J18 | N1: N07 | O1: N14 | P1: N06 | Q1: N15 | R1: S06 | S1: N09 | T1: N27
A2: 分級 | B2: 第一優先 | C2: 第二優先 | D2: 第二優先 | E2: 第二優先 | F2: 第二優先 | G2: 第二優先 | H2: 待確認實坪 | I2: 待確認實坪 | J2: 待確認實坪 | K2: 待確認實坪 | L2: 待確認實坪 | M2: 待確認實坪 | N2: 待確認實坪 | O2: 待確認實坪 | P2: 待確認實坪 | Q2: 待確認實坪 | R2: 待確認實坪 | S2: 待確認實坪 | T2: 待確認實坪
A3: 案號 | B3: S05 | C3: N04 | D3: C | E3: N02 | F3: S12 | G3: N01 | H3: N05 | I3: N08 | J3: S11 | K3: N10 | L3: N11 | M3: J18 | N3: N07 | O3: N14 | P3: N06 | Q3: N15 | R3: S06 | S3: N09 | T3: N27
A4: 案名 | B4: 建國北路二段 10F（大辦公室＋大倉儲） | C4: 信義大樓 10F | D4: 旭寶大樓 5F | E4: 廣成大廈 4F | F4: 全球人壽信義大樓 21F | G4: 南海開發大樓 5F | H4: 信義大樓 8F | I4: 松江路 3F（松江南京站） | J4: 八德大樓 5F（出租285.67坪） | K4: 光復北路11巷 2F（南京三民站） | L4: 旭寶大樓 4F | M4: 忠孝東路四段×延吉街 4F | N4: 忠孝東路一段 11F（台北車站） | O4: 中山北路三段 6F（民權西路站） | P4: 忠孝東路一段 2F（善導寺站） | Q4: 民生東路二段 6F（仲介稱使用約226坪） | R4: 八德大樓 7F（出租254.06坪） | S4: 長春路 8F（松江南京站） | T4: 南京東路五段 3F（南京三民站）
A5: 大樓 | B5: （大樓名未揭露） | C5: 全球人壽信義大樓（信義大樓） | D5: 旭寶大樓 | E5: 廣成大廈 | F5: 全球人壽信義大樓（信義大樓） | G5: 南海開發大樓 | H5: 全球人壽信義大樓（信義大樓）（推定） | I5: （大樓名未揭露） | J5: 八德大樓（591 匯幸稱） | K5: 推定：光復北路11巷35號（台北瓦斯「光復大樓」） | L5: 旭寶大樓 | M5: 推定：太平洋商業大樓（忠孝東路四段285號） | N5: （大樓名未揭露） | O5: （未揭露；同路段 6F/14F 另有「新設工大樓」刊登） | P5: （大樓名未揭露；另一刊登稱「凱撒世貿中心」） | Q5: （大樓名未揭露） | R5: 八德大樓（591 匯幸稱） | S5: （大樓名未揭露） | T5: （大樓名未揭露）
A6: 行政區 | B6: 中山 | C6: 信義 | D6: 松山 | E6: 中正 | F6: 信義 | G6: 中正 | H6: 信義 | I6: 中山 | J6: 中山 | K6: 松山 | L6: 松山 | M6: 大安 | N6: 中正 | O6: 中山 | P6: 中正 | Q6: 中山 | R6: 中山 | S6: 中山 | T6: 松山
A7: 地址 | B7: 建國北路二段 | C7: 松仁路（信義大樓） | D7: 敦化南路一段25號 | E7: 延平南路189號4樓～之5 | F7: 松仁路277號21樓 | G7: 南海路20號5樓 | H7: 松仁路（信義區） | I7: 松江路 | J7: 八德路二段 | K7: 光復北路11巷 | L7: 敦化南路一段25號 | M7: 忠孝東路4段VS延吉街 | N7: 忠孝東路一段 | O7: 中山北路三段 | P7: 忠孝東路一段 | Q7: 民生東路二段 | R7: 八德路二段 | S7: 長春路 | T7: 南京東路五段
A8: 樓層 | B8: 10F/12F | C8: 10F/23F | D8: 5F/12F(B2) | E8: 4F/7F(B2) | F8: 21F/23F(B4) | G8: 5F/10F(B1) | H8: 8F | I8: 3F/12F | J8: 5F/12F | K8: 2F/14F | L8: 4F/12F | M8: 4F | N8: 11F/12F | O8: 6F/14F | P8: 2F/21F | Q8: 6F/12F | R8: 7F/12F | S8: 8F/12F | T8: 3F/16F
A9: 權狀坪 | B9: 278.04 | C9: 330.22 | D9: 282.06 | E9: 326.85 | F9: 265.82 | G9: 260.98 | H9: 331 | I9: 302 | J9: 285.67 | K9: 283 | L9: 282.06 | M9: 276 | N9: 266.78 | O9: 265.93 | P9: 261.4 | Q9: 255.18 | R9: 254.06 | S9: 253 | T9: 243
A10: 實坪(主+附) | B10: 262.5 | C10: 300.43 | D10: 255.38 | E10: 253.54 | F10: 241.8 | G10: 228.34 | H10: 未揭露 | I10: 未揭露 | J10: 未揭露 | K10: 未揭露 | L10: 未揭露 | M10: 未揭露 | N10: 未揭露 | O10: 未揭露 | P10: 未揭露 | Q10: 未揭露 | R10: 未揭露 | S10: 未揭露 | T10: 未揭露
A11: 實坪來源 | B11: 信義房屋物件頁：主建物246.00＋附屬16.50（共有15.54） | C11: 同一戶信義房屋 C904200：主254.24＋附46.19（591 刊登「300坪」與此相符） | D11: 尚揚物調表：實用坪255.38 | E11: 尚揚物調表：主建物＋附屬建物253.54 | F11: 尚揚物調表：主建物＋附屬241.8；信義房屋 C904707：主204.94＋附36.86＝241.80 | G11: 尚揚物調表：主建物＋附屬建物228.34 | H11: 8F 本身未揭露；同棟5F/9F 實坪300.54／300.44（信義房屋） | I11: 591 原文「刊登坪數、權狀面積依地政機關登記為準」 | J11: 信義 CZ05585：整筆權狀577.14、主322.97＋附38.67（整筆），出租285.67坪部分的實坪未寫 | K11: 591 原文「廣告坪數為權狀坪數」 | L11: 591 原文「廣告顯示使用面積為含公設面積」；同棟5F 實用255.38（尚揚） | M11: 清單只有坪數276（未說明權狀或實坪） | N11: 591 原文「權狀約266.78坪、低公設比」 | O11: 591 只寫「使用坪數265.93」，無分項 | P11: 591 原文「權狀約261.4坪（室內實際使用坪數以現場丈量或地政謄本為準）」 | Q11: 591 21985150 標題「使用約226坪」（仲介口述，無謄本分項）；21595066 寫255.18坪 | R11: 信義 CZ05587：整筆權狀786.72、主322.97＋附12.15（整筆，數字異常），出租部分實坪未寫 | S11: 591 只寫「使用坪數253坪」，無分項 | T11: 591 原文「廣告坪數為權狀坪數」；公設比需≤9.5%才可能達220
A12: 公設比 | B12: 5.6% | C12: 9.0% | D12: 9.46% | E12: 22.43% | F12: 9.04% | G12: 12.51% | H12: 未揭露 | I12: 未揭露 | J12: 未揭露 | K12: 未揭露 | L12: 未揭露 | M12: 未揭露 | N12: 未揭露 | O12: 未揭露 | P12: 未揭露 | Q12: 未揭露 | R12: 未揭露 | S12: 未揭露 | T12: 未揭露
A13: 月租(含稅) | B13: 388500 | C13: 480000 | D13: 472500 | E13: 491000 | F13: 502400 | G13: 465849 | H13: 538703 | I13: 540837 | J13: 428505 | K13: 534870 | L13: 532980 | M13: 504000 | N13: 533500 | O13: 385599 | P13: 421872 | Q13: 507565 | R13: 381090 | S13: 480035 | T13: 534754
A14: 租金原文 | B14: 388,500（信義房屋刊登） | C14: 480,000（591 21537848，稅別未寫）；同戶信義房屋刊登577,885 | D14: 472,500 含稅（尚揚物調表）；591 21530071 刊登450,000（=未稅，×1.05即472,500） | E14: 491,000（尚揚物調表標示「含稅」；傑森愛華清單同價但標「未稅」；591 21779044 標491,000含管理費；591 20971276 標491,000、管理費另計31,053） | F14: 502,400 含稅（尚揚物調表）；信義房屋刊登544,931 | G14: 465,849 含稅（尚揚物調表）；591 22010357 刊登443,666（×1.05=465,849，即未稅價）；傑森愛華清單 443,000 未稅 | H14: 513,050 未稅（@1,550）→ 含稅 538,703 | I14: 515,083 未含營業稅（591 21635155）→ 含稅 540,837 | J14: 428,505（信義刊登）；591 21804249 285坪 427,500（1,500/坪） | K14: 509,400 未稅（591 22062249、傑森愛華清單第2頁）→ 含稅 534,870 | L14: 507,600 未稅（傑森愛華清單第2頁）；591 21788157 507,708 未含稅 → 含稅約533,000 | M14: 480,000 未稅（@1,739）→ 含稅 504,000（傑森愛華 9/22 與 9/23 兩份清單同價） | N14: 533,500 含稅（591 19506910） | O14: 385,599（591 22010409，含車位、含管理費，稅別未寫） | P14: 421,872（591 20214332 等7筆同價，稅別未寫）；另有 480,000（住商南門 21553405／21867832） | Q14: 483,395 未含稅（591 21595066）→ 含稅 507,565 | R14: 381,090（信義刊登）；591 22053377 254坪 381,000 | S14: 480,035（591 22061922，稅別未寫） | T14: 534,754（591 22061968，稅別未寫；若為未稅，含稅561,492將超過上限）
A15: 稅別 | B15: 頁面未寫含稅或未稅 | C15: 未寫（若為未稅，含稅為504,000） | D15: 含稅 | E15: 含稅（物調表）— 三個來源不一致 | F15: 含稅 | G15: 含稅 | H15: 未稅×1.05 | I15: 未稅×1.05 | J15: 頁面未寫 | K15: 未稅×1.05 | L15: 未稅×1.05 | M15: 未稅×1.05 | N15: 含稅 | O15: 未寫 | P15: 未寫（若為未稅，含稅為442,966） | Q15: 未稅×1.05 | R15: 頁面未寫 | S15: 未寫（若為未稅，含稅為504,037） | T15: 未寫
A16: 管理費 | B16: 約37,500（不含於租金） | C16: 約49,533（信義頁） | D16: 33,847 | E16: 31,053 | F16: 39,873（150元/坪） | G16: 實支實付（物調表：約2.5萬～3萬） | H16: 未提供（同棟約49,500） | I16: 未提供 | J16: 約47,136 | K16: 未提供 | L16: 未提供 | M16: 未提供 | N16: 未提供 | O16: 591：租金已含管理費 | P16: 未提供 | Q16: 未提供 | R16: 約41,920 | S16: 未提供 | T16: 未提供
A17: 車位 | B17: 無；平面車位可另租5,000 | C17: 591：平面式 | D17: 機械車位×6（租金內含） | E17: 固定車位7,000(含稅)／非固定5,000(含稅) | F17: 物調表未載；信義頁：無 | G17: 附坡平車位2個（591：含車位） | H17: 未提供 | I17: 未提供 | J17: 無 | K17: 未提供（傑森愛華：停車方便） | L17: 未提供 | M17: 未提供 | N17: 未提供 | O17: 含車位 | P17: 平面式 | Q17: 平面式 | R17: 無 | S17: 未提供 | T17: 未提供
A18: 押金 | B18: 2個月 | C18: — | D18: 2個月 | E18: 3個月 | F18: 3個月 | G18: 2個月 | H18: 3個月 | I18: 面議 | J18: — | K18: 3個月 | L18: 3個月 | M18: 3個月 | N18: 面議 | O18: — | P18: — | Q18: 面議 | R18: 3個月 | S18: 面議 | T18: 面議
A19: 租期 | B19: 最短2年 | C19: 591：兩年 | D19: 只能租4年（之後都更；使用者 2026-09-24 告知）；物調表寫3年 | E19: 2年 | F19: 2年（信義頁：1年） | G19: 2年 | H19: 未提供 | I19: 一年 | J19: — | K19: 3年 | L19: 最多3年約（都更） | M19: 未提供 | N19: 兩年 | O19: 兩年 | P19: 兩年 | Q19: 兩年～3年 | R19: 3年 | S19: 兩年 | T19: 兩年
A20: 屋齡／竣工 | B20: 屋齡41.7年 | C20: 屋齡約29年 | D20: 屋齡約43年（1983/12竣工，好房網） | E20: 民國70/1/5竣工（屋齡約45年） | F20: 民國86/5/25竣工（屋齡約29年） | G20: 民國77/9/22竣工（屋齡約38年） | H20: 屋齡約29年 | I20: 未提供 | J20: 屋齡30.1年 | K20: 未提供 | L20: 屋齡約43年 | M20: 推定大樓1982/08竣工（好房網） | N20: 未提供 | O20: 未提供 | P20: 未提供 | Q20: 未提供 | R20: 屋齡30.1年 | S20: 未提供 | T20: 未提供
A21: 最近綠紅藍站 | B21: 松江南京（綠）530m·約9分 | C21: 象山（紅）950m·約16分 | D21: 忠孝敦化（藍）570m·約10分 | E21: 小南門（綠）380m·約7分 | F21: 象山（紅）950m·約16分 | G21: 中正紀念堂（紅綠）150m·約3分 | H21: 象山（紅）950m·約16分 | I21: 松江南京（綠）156m·約3分 | J21: 忠孝復興（藍）620m·約11分 | K21: 南京三民（綠）88m·約2分 | L21: 忠孝敦化（藍）570m·約10分 | M21: 國父紀念館（藍）300m·約5分 | N21: 台北車站（紅藍）171m·約3分 | O21: 民權西路（紅）170m·約3分 | P21: 善導寺（藍）119m·約2分 | Q21: 行天宮(橘) 188m | R21: 忠孝復興（藍）620m·約11分 | S21: 松江南京（綠）310m·約6分 | T21: 南京三民（綠）48m·約1分
A22: 距離依據 | B22: 信義全球物件座標 | C22: 同信義大樓座標 | D22: Google地圖：敦化南路一段25號 | E22: Google地圖：延平南路189號 | F22: 信義全球物件座標 | G22: Google地圖：南海路20號 | H22: 同信義大樓座標 | I22: 591 物件頁寫明 | J22: 信義全球物件座標 | K22: 591 物件頁寫明 | L22: 同旭寶大樓座標 | M22: 忠孝東路四段×延吉街口（清單未給門牌） | N22: 591 物件頁寫明 | O22: 591 物件頁寫明 | P22: 591 物件頁寫明 | Q22: 591 只寫橘線行天宮站153～188m；綠紅藍線最近站距離未確認 | R22: 信義全球物件座標 | S22: 591 物件頁寫明 | T22: 591 物件頁寫明
